Workbook

Sheet MANUAL_DE_USUARIO_Y_TEORIA
B1: MANUAL DE TEORÍA Y GUÍA DE USUARIO - MÉTODO DE RIGIDEZ DIRECTA
B2: Cátedra: Análisis Estructural II | Ing. Ulianov Cuba Valencia | Ejemplos Resueltos y Plantillas Configurables
B4: 1. SUSTENTACIÓN TEÓRICA Y CAPTURAS REALES DEL INGENIERO
B5: El Método de la Rigidez Directa (Matricial) formula el equilibrio de la estructura en función de los desplazamientos de los nudos como incógnitas fundamentales. Cada nudo posee dos grados de libertad ortogonales (X e Y), y cada barra aporta rigidez axial según su orientación y propiedades mecánicas (A, E, L). A continuación se presentan las capturas directas de las clases y guías académicas del docente que sustentan cada paso del sistema:
B24: ▲ Captura 1: Esquema de Armadura y Matrices Locales 4x4 (Apunte de Clase del Ingeniero) | G24: ▲ Captura 2: Asistente Interactivo con Grados de Libertad y Diagnóstico GH (Clase del Ingeniero)
B42: ▲ Captura 3: Hoja Automatizada del Docente con Gráfico y Tabla de Conectividad (Hoja1) | G42: ▲ Captura 4: Ecuación Global Matricial {C} = [K] · {D} y Desplazamientos del Profesor
G44: ⭐ EJEMPLO 4 RESUELTO: ARMADURA ASIMÉTRICA 4N-5B (CÁTEDRA ULIANOV)
G45: • Origen: Problema oficial de examen de la cátedra Ing. Ulianov Cuba (4 Nudos, 5 Barras).
G46: • Geometría: N1(0, 0) Fijo | N2(1000, 0) Rodillo Y | N3(200, 400) | N4(800, 800) Cumbrera.
G47: • Propiedades mecánicas: Módulo E = 120,000 Kgf/cm² | Área de sección A = 16.00 cm².
G48: • Solicitaciones aplicadas: Nudo 3: (+7800 Kgf, -7800 Kgf) | Nudo 4: (+6000 Kgf, -6000 Kgf).
G49: • Conectividad de barras: 1(1→2), 2(1→3), 3(3→2), 4(3→4), 5(4→2).
G50: • Reacciones teóricas exactas: C1X = -13,800.00 Kgf | C1Y = -480.00 Kgf | C2Y = +14,280.00 Kgf.
G51: • Equilibrio global: ΣFx = 0 (+7800 + 6000 - 13800 = 0) | ΣFy = 0 (-7800 - 6000 - 480 + 14280 = 0).
G52: • Fuerzas axiales verificadas: N1 = +13,560.00 Kgf (T) | N2 = +536.66 Kgf (T) | N3 = -12,764.75 Kgf (C)
G53: N4 = +4,635.71 Kgf (T) | N5 = -8,835.23 Kgf (C).
G54: • Estado en la suite: CASO 06 (Hoja GRAFICA_06 y AUTOMATIZADA_06) 100% resuelto y verificado.
B60: ▲ Captura 5: Ejercicio Oficial de Cátedra Ulianov (Armadura Asimétrica 4N-5B Resuelta al 100%)
B62: 2. CRITERIO DE DETERMINACIÓN ESTÁTICA Y FÓRMULAS DE CÁLCULO
B63: GRADO DE HIPERESTATICIDAD | C63: GH = b + r - 2j | E63: b = número de barras activas, r = número de reacciones en apoyos, j = número de nudos.
B64: CASO ISOSTÁTICO (GH = 0) | C64: b + r = 2j (Estable) | E64: La estructura es estáticamente determinada. Se resuelve exactamente por el método matricial.
B65: CASO HIPERESTÁTICO (GH > 0) | C65: b + r > 2j (Indeterminado) | E65: Posee barras redundantes internas o apoyos supernumerarios. Resuelto rigurosamente por rigidez.
B66: MATRIZ LOCAL DE BARRA (4x4) | C66: k_i = (AE/L) · [[Cx², CxCy, -Cx², -CxCy], ...] | E66: Cx = cos θ = DX/L, Cy = sen θ = DY/L. Vincula desplazamientos locales con globales.
B67: FUERZA AXIAL EN BARRA | C67: Ni = (AE/L) · [-Cx, -Cy, Cx, Cy] · {u} | E67: Ni > 0 indica TRACCIÓN (+), Ni < 0 indica COMPRESIÓN (-), Ni = 0 es FUERZA NULA.
B70: 3. CATÁLOGO MAESTRO DE MOLDES Y TOPOLOGÍAS ESTRUCTURALES (GUÍA RÁPIDA)
B71: GRUPO 1: 3 NUDOS / 3 BARRAS | C71: Casos 01 a 05 | D71: Triángulos simétricos, asimétricos, ménsulas de pared y techos tendidos de gran luz.
B72: GRUPO 2: 4 NUDOS / 5 BARRAS (10 MOLDES) | C72: Casos 06 a 15 | D72: ⭐ Caso 06 Ulianov, Caballete 2 aguas, Shed diente de sierra, Pratt, Howe, Torres trapezoidales, Abanico y Romboide.
B73: GRUPO 3: 5 NUDOS / 7 BARRAS (10 MOLDES) | C73: Casos 16 a 25 | D73: Warren clásica, Caballete con tornapunta, Pratt extremo recto, Howe, Ménsula de punta, Polonceau quebrado, Torre.
B74: GRUPO 4: 6 NUDOS / 9 BARRAS (10 MOLDES) | C74: Casos 26 a 35 | D74: Warren 3 paneles, Pratt, Howe, Fink con pendolón, Celosía K voladizo, Mansarda francesa, Marquesina de estadio.
B75: GRUPO 5: 7 Y 8 NUDOS DE GRAN ESCALA | C75: Casos 36 a 40 | D75: Warren extensa 4 paneles, Pratt múltiple, Celosía continua Polonceau, Puentes ferroviarios y Naves industriales.
B76: GRUPO 6: ARMADURAS HIPERESTÁTICAS | C76: Casos 41 a 70 | D76: 30 estructuras hiperestáticas comunes (GH=1 a GH=5) con arriostramientos en Cruz de San Andrés, vigas continuas, ménsulas empotradas y puentes multirótula.
B79: 4. SUPER PLANTILLAS MANUALES UNIVERSALES Y ACCESO DIRECTO A LOS 70 CASOS
B80: CASO # | C80: TIPO / ROL | D80: NOMBRE / TIPOLOGÍA | E80: NUDOS (j) | F80: BARRAS (b) | G80: REAC. (r) | H80: GRADO GH | I80: CLASIFICACIÓN | J80: GRÁFICA Y ASISTENTE (COORDENADAS EN CM) | K80: SOLUCIÓN MATRICIAL (AUTOMATIZADA)
B81: 1 | C81: ⭐ Ejemplo Resuelto | D81: Armadura Triangular WhatsApp (Caso 2 Original) | E81: 3 | F81: 3 | G81: 3 | H81: 0 | I81: ✅ Isostática (GH=0) | J81: =HYPERLINK("#'GRAFICA_01'!A1", "📈 Ir a Gráfica 01") -> 📈 Ir a Gráfica 01 | K81: =HYPERLINK("#'AUTOMATIZADA_01'!A1", "📊 Ir a Hoja 01") -> 📊 Ir a Hoja 01
B82: 2 | C82: ⭐ Ejemplo Resuelto | D82: Armadura Triangular Profesor (Caso 1 Original) | E82: 3 | F82: 3 | G82: 3 | H82: 0 | I82: ✅ Isostática (GH=0) | J82: =HYPERLINK("#'GRAFICA_02'!A1", "📈 Ir a Gráfica 02") -> 📈 Ir a Gráfica 02 | K82: =HYPERLINK("#'AUTOMATIZADA_02'!A1", "📊 Ir a Hoja 02") -> 📊 Ir a Hoja 02
B83: 3 | C83: ⭐ Ejemplo Resuelto | D83: Triángulo Equilátero de Cubierta | E83: 3 | F83: 3 | G83: 3 | H83: 0 | I83: ✅ Isostática (GH=0) | J83: =HYPERLINK("#'GRAFICA_03'!A1", "📈 Ir a Gráfica 03") -> 📈 Ir a Gráfica 03 | K83: =HYPERLINK("#'AUTOMATIZADA_03'!A1", "📊 Ir a Hoja 03") -> 📊 Ir a Hoja 03
B84: 4 | C84: 📋 Plantilla Configurable | D84: Ménsula Triangular Rectángulo | E84: 3 | F84: 3 | G84: 3 | H84: 0 | I84: ✅ Isostática (GH=0) | J84: =HYPERLINK("#'GRAFICA_04'!A1", "📈 Ir a Gráfica 04") -> 📈 Ir a Gráfica 04 | K84: =HYPERLINK("#'AUTOMATIZADA_04'!A1", "📊 Ir a Hoja 04") -> 📊 Ir a Hoja 04
B85: 5 | C85: 📋 Plantilla Configurable | D85: Armadura de Techo Tendido | E85: 3 | F85: 3 | G85: 3 | H85: 0 | I85: ✅ Isostática (GH=0) | J85: =HYPERLINK("#'GRAFICA_05'!A1", "📈 Ir a Gráfica 05") -> 📈 Ir a Gráfica 05 | K85: =HYPERLINK("#'AUTOMATIZADA_05'!A1", "📊 Ir a Hoja 05") -> 📊 Ir a Hoja 05
B86: 6 | C86: ⭐ Ejemplo Resuelto | D86: Armadura Asimétrica 4 Nudos y 5 Barras (Cátedra Ulianov) | E86: 4 | F86: 5 | G86: 3 | H86: 0 | I86: ✅ Isostática (GH=0) | J86: =HYPERLINK("#'GRAFICA_06'!A1", "📈 Ir a Gráfica 06") -> 📈 Ir a Gráfica 06 | K86: =HYPERLINK("#'AUTOMATIZADA_06'!A1", "📊 Ir a Hoja 06") -> 📊 Ir a Hoja 06
B87: 7 | C87: 📋 Plantilla Configurable | D87: Caballete Simétrico de Dos Aguas | E87: 4 | F87: 5 | G87: 3 | H87: 0 | I87: ✅ Isostática (GH=0) | J87: =HYPERLINK("#'GRAFICA_07'!A1", "📈 Ir a Gráfica 07") -> 📈 Ir a Gráfica 07 | K87: =HYPERLINK("#'AUTOMATIZADA_07'!A1", "📊 Ir a Hoja 07") -> 📊 Ir a Hoja 07
...

Sheet MANUAL_ISOSTATICA_3R
A1: PLANTILLA MANUAL - CASO ISOSTÁTICO (HASTA 6 NODOS Y 8 BARRAS - CÁTEDRA ING. ULIANOV)
A2: Cátedra: Análisis Estructural II | Ing. Ulianov Cuba Valencia | Plantilla 100% Automatizada con Capacidad hasta 6 Nodos y 8 Barras
B4: BARRA | C4: INICIO (cm) | E4: FIN (cm) | G4: DX (cm) | H4: DY (cm) | I4: L (cm) | J4: Cx | K4: Cy | L4: A (cm²) | M4: E (Kgf/cm²) | N4: AE/L (Kgf/cm) | P4: COORDENADAS, CONDICIONES DE APOYO Y CARGAS NODALES (HASTA 6 NODOS)
C5: X | D5: Y | E5: X | F5: Y | P5: NUDO | Q5: X (cm) | R5: Y (cm) | S5: TIPO APOYO | T5: Rx | U5: Ry | V5: Px (Kgf) | W5: Py (Kgf)
B6: 1 | C6: =IF(C17="","", IFERROR(VLOOKUP(C17, $P$6:$W$11, 2, FALSE), "")) -> 0 | D6: =IF(C17="","", IFERROR(VLOOKUP(C17, $P$6:$W$11, 3, FALSE), "")) -> 0 | E6: =IF(F17="","", IFERROR(VLOOKUP(F17, $P$6:$W$11, 2, FALSE), "")) -> 1000 | F6: =IF(F17="","", IFERROR(VLOOKUP(F17, $P$6:$W$11, 3, FALSE), "")) -> 0 | G6: =IF(OR(C6="",E6=""), "", E6-C6) -> 1000 | H6: =IF(OR(D6="",F6=""), "", F6-D6) -> 0 | I6: =IF(OR(G6="",H6=""), "", SQRT(G6^2+H6^2)) -> 1000 | J6: =IF(OR(I6="",I6=0), "", G6/I6) -> 1 | K6: =IF(OR(I6="",I6=0), "", H6/I6) -> 0 | L6: =IF(C17="","", 16) -> 16 | M6: =IF(C17="","", 120000) -> 120000 | N6: =IF(OR(I6="",I6=0,L6="",M6=""), 0, (L6*M6)/I6) -> 1920 | P6: 1 | Q6: 0 | R6: 0 | S6: Fijo | T6: =IF(Q6="","", IF(LEFT(UPPER(TRIM(S6)),4)="FIJO", 1, IF(OR(UPPER(TRIM(S6))="MOVIL X", UPPER(TRIM(S6))="MÓVIL X", UPPER(TRIM(S6))="RODILLO X"), 1, 0))) -> 1 | U6: =IF(Q6="","", IF(LEFT(UPPER(TRIM(S6)),4)="FIJO", 1, IF(OR(UPPER(TRIM(S6))="MOVIL Y", UPPER(TRIM(S6))="MÓVIL Y", UPPER(TRIM(S6))="RODILLO Y", UPPER(TRIM(S6))="MOVIL", UPPER(TRIM(S6))="MÓVIL"), 1, 0))) -> 1 | V6: 0 | W6: 0
B7: 2 | C7: =IF(C18="","", IFERROR(VLOOKUP(C18, $P$6:$W$11, 2, FALSE), "")) -> 0 | D7: =IF(C18="","", IFERROR(VLOOKUP(C18, $P$6:$W$11, 3, FALSE), "")) -> 0 | E7: =IF(F18="","", IFERROR(VLOOKUP(F18, $P$6:$W$11, 2, FALSE), "")) -> 200 | F7: =IF(F18="","", IFERROR(VLOOKUP(F18, $P$6:$W$11, 3, FALSE), "")) -> 400 | G7: =IF(OR(C7="",E7=""), "", E7-C7) -> 200 | H7: =IF(OR(D7="",F7=""), "", F7-D7) -> 400 | I7: =IF(OR(G7="",H7=""), "", SQRT(G7^2+H7^2)) -> 447.2136 | J7: =IF(OR(I7="",I7=0), "", G7/I7) -> 0.4472136 | K7: =IF(OR(I7="",I7=0), "", H7/I7) -> 0.89442719 | L7: =IF(C18="","", 16) -> 16 | M7: =IF(C18="","", 120000) -> 120000 | N7: =IF(OR(I7="",I7=0,L7="",M7=""), 0, (L7*M7)/I7) -> 4293.2505 | P7: 2 | Q7: 1000 | R7: 0 | S7: Móvil Y | T7: =IF(Q7="","", IF(LEFT(UPPER(TRIM(S7)),4)="FIJO", 1, IF(OR(UPPER(TRIM(S7))="MOVIL X", UPPER(TRIM(S7))="MÓVIL X", UPPER(TRIM(S7))="RODILLO X"), 1, 0))) -> 0 | U7: =IF(Q7="","", IF(LEFT(UPPER(TRIM(S7)),4)="FIJO", 1, IF(OR(UPPER(TRIM(S7))="MOVIL Y", UPPER(TRIM(S7))="MÓVIL Y", UPPER(TRIM(S7))="RODILLO Y", UPPER(TRIM(S7))="MOVIL", UPPER(TRIM(S7))="MÓVIL"), 1, 0))) -> 1 | V7: 0 | W7: 0
B8: 3 | C8: =IF(C19="","", IFERROR(VLOOKUP(C19, $P$6:$W$11, 2, FALSE), "")) -> 200 | D8: =IF(C19="","", IFERROR(VLOOKUP(C19, $P$6:$W$11, 3, FALSE), "")) -> 400 | E8: =IF(F19="","", IFERROR(VLOOKUP(F19, $P$6:$W$11, 2, FALSE), "")) -> 1000 | F8: =IF(F19="","", IFERROR(VLOOKUP(F19, $P$6:$W$11, 3, FALSE), "")) -> 0 | G8: =IF(OR(C8="",E8=""), "", E8-C8) -> 800 | H8: =IF(OR(D8="",F8=""), "", F8-D8) -> -400 | I8: =IF(OR(G8="",H8=""), "", SQRT(G8^2+H8^2)) -> 894.42719 | J8: =IF(OR(I8="",I8=0), "", G8/I8) -> 0.89442719 | K8: =IF(OR(I8="",I8=0), "", H8/I8) -> -0.4472136 | L8: =IF(C19="","", 16) -> 16 | M8: =IF(C19="","", 120000) -> 120000 | N8: =IF(OR(I8="",I8=0,L8="",M8=""), 0, (L8*M8)/I8) -> 2146.6253 | P8: 3 | Q8: 200 | R8: 400 | S8: Libre | T8: =IF(Q8="","", IF(LEFT(UPPER(TRIM(S8)),4)="FIJO", 1, IF(OR(UPPER(TRIM(S8))="MOVIL X", UPPER(TRIM(S8))="MÓVIL X", UPPER(TRIM(S8))="RODILLO X"), 1, 0))) -> 0 | U8: =IF(Q8="","", IF(LEFT(UPPER(TRIM(S8)),4)="FIJO", 1, IF(OR(UPPER(TRIM(S8))="MOVIL Y", UPPER(TRIM(S8))="MÓVIL Y", UPPER(TRIM(S8))="RODILLO Y", UPPER(TRIM(S8))="MOVIL", UPPER(TRIM(S8))="MÓVIL"), 1, 0))) -> 0 | V8: 7800 | W8: -7800
B9: 4 | C9: =IF(C20="","", IFERROR(VLOOKUP(C20, $P$6:$W$11, 2, FALSE), "")) -> 200 | D9: =IF(C20="","", IFERROR(VLOOKUP(C20, $P$6:$W$11, 3, FALSE), "")) -> 400 | E9: =IF(F20="","", IFERROR(VLOOKUP(F20, $P$6:$W$11, 2, FALSE), "")) -> 800 | F9: =IF(F20="","", IFERROR(VLOOKUP(F20, $P$6:$W$11, 3, FALSE), "")) -> 800 | G9: =IF(OR(C9="",E9=""), "", E9-C9) -> 600 | H9: =IF(OR(D9="",F9=""), "", F9-D9) -> 400 | I9: =IF(OR(G9="",H9=""), "", SQRT(G9^2+H9^2)) -> 721.11026 | J9: =IF(OR(I9="",I9=0), "", G9/I9) -> 0.83205029 | K9: =IF(OR(I9="",I9=0), "", H9/I9) -> 0.5547002 | L9: =IF(C20="","", 16) -> 16 | M9: =IF(C20="","", 120000) -> 120000 | N9: =IF(OR(I9="",I9=0,L9="",M9=""), 0, (L9*M9)/I9) -> 2662.5609 | P9: 4 | Q9: 800 | R9: 800 | S9: Libre | T9: =IF(Q9="","", IF(LEFT(UPPER(TRIM(S9)),4)="FIJO", 1, IF(OR(UPPER(TRIM(S9))="MOVIL X", UPPER(TRIM(S9))="MÓVIL X", UPPER(TRIM(S9))="RODILLO X"), 1, 0))) -> 0 | U9: =IF(Q9="","", IF(LEFT(UPPER(TRIM(S9)),4)="FIJO", 1, IF(OR(UPPER(TRIM(S9))="MOVIL Y", UPPER(TRIM(S9))="MÓVIL Y", UPPER(TRIM(S9))="RODILLO Y", UPPER(TRIM(S9))="MOVIL", UPPER(TRIM(S9))="MÓVIL"), 1, 0))) -> 0 | V9: 6000 | W9: -6000
B10: 5 | C10: =IF(C21="","", IFERROR(VLOOKUP(C21, $P$6:$W$11, 2, FALSE), "")) -> 800 | D10: =IF(C21="","", IFERROR(VLOOKUP(C21, $P$6:$W$11, 3, FALSE), "")) -> 800 | E10: =IF(F21="","", IFERROR(VLOOKUP(F21, $P$6:$W$11, 2, FALSE), "")) -> 1000 | F10: =IF(F21="","", IFERROR(VLOOKUP(F21, $P$6:$W$11, 3, FALSE), "")) -> 0 | G10: =IF(OR(C10="",E10=""), "", E10-C10) -> 200 | H10: =IF(OR(D10="",F10=""), "", F10-D10) -> -800 | I10: =IF(OR(G10="",H10=""), "", SQRT(G10^2+H10^2)) -> 824.62113 | J10: =IF(OR(I10="",I10=0), "", G10/I10) -> 0.24253563 | K10: =IF(OR(I10="",I10=0), "", H10/I10) -> -0.9701425 | L10: =IF(C21="","", 16) -> 16 | M10: =IF(C21="","", 120000) -> 120000 | N10: =IF(OR(I10="",I10=0,L10="",M10=""), 0, (L10*M10)/I10) -> 2328.342 | P10: 5 | T10: =IF(Q10="","", IF(LEFT(UPPER(TRIM(S10)),4)="FIJO", 1, IF(OR(UPPER(TRIM(S10))="MOVIL X", UPPER(TRIM(S10))="MÓVIL X", UPPER(TRIM(S10))="RODILLO X"), 1, 0))) | U10: =IF(Q10="","", IF(LEFT(UPPER(TRIM(S10)),4)="FIJO", 1, IF(OR(UPPER(TRIM(S10))="MOVIL Y", UPPER(TRIM(S10))="MÓVIL Y", UPPER(TRIM(S10))="RODILLO Y", UPPER(TRIM(S10))="MOVIL", UPPER(TRIM(S10))="MÓVIL"), 1, 0)))
B11: 6 | C11: =IF(C22="","", IFERROR(VLOOKUP(C22, $P$6:$W$11, 2, FALSE), "")) | D11: =IF(C22="","", IFERROR(VLOOKUP(C22, $P$6:$W$11, 3, FALSE), "")) | E11: =IF(F22="","", IFERROR(VLOOKUP(F22, $P$6:$W$11, 2, FALSE), "")) | F11: =IF(F22="","", IFERROR(VLOOKUP(F22, $P$6:$W$11, 3, FALSE), "")) | G11: =IF(OR(C11="",E11=""), "", E11-C11) | H11: =IF(OR(D11="",F11=""), "", F11-D11) | I11: =IF(OR(G11="",H11=""), "", SQRT(G11^2+H11^2)) | J11: =IF(OR(I11="",I11=0), "", G11/I11) | K11: =IF(OR(I11="",I11=0), "", H11/I11) | L11: =IF(C22="","", 10) | M11: =IF(C22="","", 2100000) | N11: =IF(OR(I11="",I11=0,L11="",M11=""), 0, (L11*M11)/I11) -> 0 | P11: 6 | T11: =IF(Q11="","", IF(LEFT(UPPER(TRIM(S11)),4)="FIJO", 1, IF(OR(UPPER(TRIM(S11))="MOVIL X", UPPER(TRIM(S11))="MÓVIL X", UPPER(TRIM(S11))="RODILLO X"), 1, 0))) | U11: =IF(Q11="","", IF(LEFT(UPPER(TRIM(S11)),4)="FIJO", 1, IF(OR(UPPER(TRIM(S11))="MOVIL Y", UPPER(TRIM(S11))="MÓVIL Y", UPPER(TRIM(S11))="RODILLO Y", UPPER(TRIM(S11))="MOVIL", UPPER(TRIM(S11))="MÓVIL"), 1, 0)))
B12: 7 | C12: =IF(C23="","", IFERROR(VLOOKUP(C23, $P$6:$W$11, 2, FALSE), "")) | D12: =IF(C23="","", IFERROR(VLOOKUP(C23, $P$6:$W$11, 3, FALSE), "")) | E12: =IF(F23="","", IFERROR(VLOOKUP(F23, $P$6:$W$11, 2, FALSE), "")) | F12: =IF(F23="","", IFERROR(VLOOKUP(F23, $P$6:$W$11, 3, FALSE), "")) | G12: =IF(OR(C12="",E12=""), "", E12-C12) | H12: =IF(OR(D12="",F12=""), "", F12-D12) | I12: =IF(OR(G12="",H12=""), "", SQRT(G12^2+H12^2)) | J12: =IF(OR(I12="",I12=0), "", G12/I12) | K12: =IF(OR(I12="",I12=0), "", H12/I12) | L12: =IF(C23="","", 10) | M12: =IF(C23="","", 2100000) | N12: =IF(OR(I12="",I12=0,L12="",M12=""), 0, (L12*M12)/I12) -> 0
B13: 8 | C13: =IF(C24="","", IFERROR(VLOOKUP(C24, $P$6:$W$11, 2, FALSE), "")) | D13: =IF(C24="","", IFERROR(VLOOKUP(C24, $P$6:$W$11, 3, FALSE), "")) | E13: =IF(F24="","", IFERROR(VLOOKUP(F24, $P$6:$W$11, 2, FALSE), "")) | F13: =IF(F24="","", IFERROR(VLOOKUP(F24, $P$6:$W$11, 3, FALSE), "")) | G13: =IF(OR(C13="",E13=""), "", E13-C13) | H13: =IF(OR(D13="",F13=""), "", F13-D13) | I13: =IF(OR(G13="",H13=""), "", SQRT(G13^2+H13^2)) | J13: =IF(OR(I13="",I13=0), "", G13/I13) | K13: =IF(OR(I13="",I13=0), "", H13/I13) | L13: =IF(C24="","", 10) | M13: =IF(C24="","", 2100000) | N13: =IF(OR(I13="",I13=0,L13="",M13=""), 0, (L13*M13)/I13) -> 0
B15: CONECTIVIDAD DE BARRAS Y GRADOS DE LIBERTAD ASOCIADOS:
B16: BARRA | C16: NUDO INICIO | D16: u_ini_x | E16: u_ini_y | F16: NUDO FIN | G16: u_fin_x | H16: u_fin_y | S16: Móvil Y
B17: 1 | C17: 1 | D17: =IF(C17="","", "U" & C17 & "X") -> U1X | E17: =IF(C17="","", "U" & C17 & "Y") -> U1Y | F17: 2 | G17: =IF(F17="","", "U" & F17 & "X") -> U2X | H17: =IF(F17="","", "U" & F17 & "Y") -> U2Y | S17: Fijo
B18: 2 | C18: 1 | D18: =IF(C18="","", "U" & C18 & "X") -> U1X | E18: =IF(C18="","", "U" & C18 & "Y") -> U1Y | F18: 3 | G18: =IF(F18="","", "U" & F18 & "X") -> U3X | H18: =IF(F18="","", "U" & F18 & "Y") -> U3Y | S18: Libre
B19: 3 | C19: 3 | D19: =IF(C19="","", "U" & C19 & "X") -> U3X | E19: =IF(C19="","", "U" & C19 & "Y") -> U3Y | F19: 2 | G19: =IF(F19="","", "U" & F19 & "X") -> U2X | H19: =IF(F19="","", "U" & F19 & "Y") -> U2Y | S19: Libre
B20: 4 | C20: 3 | D20: =IF(C20="","", "U" & C20 & "X") -> U3X | E20: =IF(C20="","", "U" & C20 & "Y") -> U3Y | F20: 4 | G20: =IF(F20="","", "U" & F20 & "X") -> U4X | H20: =IF(F20="","", "U" & F20 & "Y") -> U4Y | S20: Libre
B21: 5 | C21: 4 | D21: =IF(C21="","", "U" & C21 & "X") -> U4X | E21: =IF(C21="","", "U" & C21 & "Y") -> U4Y | F21: 2 | G21: =IF(F21="","", "U" & F21 & "X") -> U2X | H21: =IF(F21="","", "U" & F21 & "Y") -> U2Y | S21: Libre
B22: 6 | D22: =IF(C22="","", "U" & C22 & "X") | E22: =IF(C22="","", "U" & C22 & "Y") | G22: =IF(F22="","", "U" & F22 & "X") | H22: =IF(F22="","", "U" & F22 & "Y")
B23: 7 | D23: =IF(C23="","", "U" & C23 & "X") | E23: =IF(C23="","", "U" & C23 & "Y") | G23: =IF(F23="","", "U" & F23 & "X") | H23: =IF(F23="","", "U" & F23 & "Y")
B24: 8 | D24: =IF(C24="","", "U" & C24 & "X") | E24: =IF(C24="","", "U" & C24 & "Y") | G24: =IF(F24="","", "U" & F24 & "X") | H24: =IF(F24="","", "U" & F24 & "Y")
A27: k1= | B27: =IF(D17="","-",D17) -> U1X | C27: =IF(E17="","-",E17) -> U1Y | D27: =IF(G17="","-",G17) -> U2X | E27: =IF(H17="","-",H17) -> U2Y
B28: =IF(N6=0, 0, N6*J6*J6) -> 1920 | C28: =IF(N6=0, 0, N6*J6*K6) -> 0 | D28: =IF(N6=0, 0, -N6*J6*J6) -> -1920 | E28: =IF(N6=0, 0, -N6*J6*K6) -> 0 | F28: =IF(D17="","-",D17) -> U1X
B29: =IF(N6=0, 0, N6*J6*K6) -> 0 | C29: =IF(N6=0, 0, N6*K6*K6) -> 0 | D29: =IF(N6=0, 0, -N6*J6*K6) -> 0 | E29: =IF(N6=0, 0, -N6*K6*K6) -> 0 | F29: =IF(E17="","-",E17) -> U1Y
B30: =IF(N6=0, 0, -N6*J6*J6) -> -1920 | C30: =IF(N6=0, 0, -N6*J6*K6) -> 0 | D30: =IF(N6=0, 0, N6*J6*J6) -> 1920 | E30: =IF(N6=0, 0, N6*J6*K6) -> 0 | F30: =IF(G17="","-",G17) -> U2X
B31: =IF(N6=0, 0, -N6*J6*K6) -> 0 | C31: =IF(N6=0, 0, -N6*K6*K6) -> 0 | D31: =IF(N6=0, 0, N6*J6*K6) -> 0 | E31: =IF(N6=0, 0, N6*K6*K6) -> 0 | F31: =IF(H17="","-",H17) -> U2Y
B33: U1X | C33: U1Y | D33: U2X | E33: U2Y | F33: U3X | G33: U3Y | H33: U4X | I33: U4Y | J33: U5X | K33: U5Y | L33: U6X | M33: U6Y
B34: =IFERROR(INDEX($B$28:$E$31, MATCH($N34, $B$27:$E$27, 0), MATCH(B$33, $B$27:$E$27, 0)), 0) -> 1920 | C34: =IFERROR(INDEX($B$28:$E$31, MATCH($N34, $B$27:$E$27, 0), MATCH(C$33, $B$27:$E$27, 0)), 0) -> 0 | D34: =IFERROR(INDEX($B$28:$E$31, MATCH($N34, $B$27:$E$27, 0), MATCH(D$33, $B$27:$E$27, 0)), 0) -> -1920 | E34: =IFERROR(INDEX($B$28:$E$31, MATCH($N34, $B$27:$E$27, 0), MATCH(E$33, $B$27:$E$27, 0)), 0) -> 0 | F34: =IFERROR(INDEX($B$28:$E$31, MATCH($N34, $B$27:$E$27, 0), MATCH(F$33, $B$27:$E$27, 0)), 0) -> 0 | G34: =IFERROR(INDEX($B$28:$E$31, MATCH($N34, $B$27:$E$27, 0), MATCH(G$33, $B$27:$E$27, 0)), 0) -> 0 | H34: =IFERROR(INDEX($B$28:$E$31, MATCH($N34, $B$27:$E$27, 0), MATCH(H$33, $B$27:$E$27, 0)), 0) -> 0 | I34: =IFERROR(INDEX($B$28:$E$31, MATCH($N34, $B$27:$E$27, 0), MATCH(I$33, $B$27:$E$27, 0)), 0) -> 0 | ... M34: =IFERROR(INDEX($B$28:$E$31, MATCH($N34, $B$27:$E$27, 0), MATCH(M$33, $B$27:$E$27, 0)), 0) -> 0 | N34: U1X
B35: =IFERROR(INDEX($B$28:$E$31, MATCH($N35, $B$27:$E$27, 0), MATCH(B$33, $B$27:$E$27, 0)), 0) -> 0 | C35: =IFERROR(INDEX($B$28:$E$31, MATCH($N35, $B$27:$E$27, 0), MATCH(C$33, $B$27:$E$27, 0)), 0) -> 0 | D35: =IFERROR(INDEX($B$28:$E$31, MATCH($N35, $B$27:$E$27, 0), MATCH(D$33, $B$27:$E$27, 0)), 0) -> 0 | E35: =IFERROR(INDEX($B$28:$E$31, MATCH($N35, $B$27:$E$27, 0), MATCH(E$33, $B$27:$E$27, 0)), 0) -> 0 | F35: =IFERROR(INDEX($B$28:$E$31, MATCH($N35, $B$27:$E$27, 0), MATCH(F$33, $B$27:$E$27, 0)), 0) -> 0 | G35: =IFERROR(INDEX($B$28:$E$31, MATCH($N35, $B$27:$E$27, 0), MATCH(G$33, $B$27:$E$27, 0)), 0) -> 0 | H35: =IFERROR(INDEX($B$28:$E$31, MATCH($N35, $B$27:$E$27, 0), MATCH(H$33, $B$27:$E$27, 0)), 0) -> 0 | I35: =IFERROR(INDEX($B$28:$E$31, MATCH($N35, $B$27:$E$27, 0), MATCH(I$33, $B$27:$E$27, 0)), 0) -> 0 | ... M35: =IFERROR(INDEX($B$28:$E$31, MATCH($N35, $B$27:$E$27, 0), MATCH(M$33, $B$27:$E$27, 0)), 0) -> 0 | N35: U1Y
B36: =IFERROR(INDEX($B$28:$E$31, MATCH($N36, $B$27:$E$27, 0), MATCH(B$33, $B$27:$E$27, 0)), 0) -> -1920 | C36: =IFERROR(INDEX($B$28:$E$31, MATCH($N36, $B$27:$E$27, 0), MATCH(C$33, $B$27:$E$27, 0)), 0) -> 0 | D36: =IFERROR(INDEX($B$28:$E$31, MATCH($N36, $B$27:$E$27, 0), MATCH(D$33, $B$27:$E$27, 0)), 0) -> 1920 | E36: =IFERROR(INDEX($B$28:$E$31, MATCH($N36, $B$27:$E$27, 0), MATCH(E$33, $B$27:$E$27, 0)), 0) -> 0 | F36: =IFERROR(INDEX($B$28:$E$31, MATCH($N36, $B$27:$E$27, 0), MATCH(F$33, $B$27:$E$27, 0)), 0) -> 0 | G36: =IFERROR(INDEX($B$28:$E$31, MATCH($N36, $B$27:$E$27, 0), MATCH(G$33, $B$27:$E$27, 0)), 0) -> 0 | H36: =IFERROR(INDEX($B$28:$E$31, MATCH($N36, $B$27:$E$27, 0), MATCH(H$33, $B$27:$E$27, 0)), 0) -> 0 | I36: =IFERROR(INDEX($B$28:$E$31, MATCH($N36, $B$27:$E$27, 0), MATCH(I$33, $B$27:$E$27, 0)), 0) -> 0 | ... M36: =IFERROR(INDEX($B$28:$E$31, MATCH($N36, $B$27:$E$27, 0), MATCH(M$33, $B$27:$E$27, 0)), 0) -> 0 | N36: U2X
B37: =IFERROR(INDEX($B$28:$E$31, MATCH($N37, $B$27:$E$27, 0), MATCH(B$33, $B$27:$E$27, 0)), 0) -> 0 | C37: =IFERROR(INDEX($B$28:$E$31, MATCH($N37, $B$27:$E$27, 0), MATCH(C$33, $B$27:$E$27, 0)), 0) -> 0 | D37: =IFERROR(INDEX($B$28:$E$31, MATCH($N37, $B$27:$E$27, 0), MATCH(D$33, $B$27:$E$27, 0)), 0) -> 0 | E37: =IFERROR(INDEX($B$28:$E$31, MATCH($N37, $B$27:$E$27, 0), MATCH(E$33, $B$27:$E$27, 0)), 0) -> 0 | F37: =IFERROR(INDEX($B$28:$E$31, MATCH($N37, $B$27:$E$27, 0), MATCH(F$33, $B$27:$E$27, 0)), 0) -> 0 | G37: =IFERROR(INDEX($B$28:$E$31, MATCH($N37, $B$27:$E$27, 0), MATCH(G$33, $B$27:$E$27, 0)), 0) -> 0 | H37: =IFERROR(INDEX($B$28:$E$31, MATCH($N37, $B$27:$E$27, 0), MATCH(H$33, $B$27:$E$27, 0)), 0) -> 0 | I37: =IFERROR(INDEX($B$28:$E$31, MATCH($N37, $B$27:$E$27, 0), MATCH(I$33, $B$27:$E$27, 0)), 0) -> 0 | ... M37: =IFERROR(INDEX($B$28:$E$31, MATCH($N37, $B$27:$E$27, 0), MATCH(M$33, $B$27:$E$27, 0)), 0) -> 0 | N37: U2Y
B38: =IFERROR(INDEX($B$28:$E$31, MATCH($N38, $B$27:$E$27, 0), MATCH(B$33, $B$27:$E$27, 0)), 0) -> 0 | C38: =IFERROR(INDEX($B$28:$E$31, MATCH($N38, $B$27:$E$27, 0), MATCH(C$33, $B$27:$E$27, 0)), 0) -> 0 | D38: =IFERROR(INDEX($B$28:$E$31, MATCH($N38, $B$27:$E$27, 0), MATCH(D$33, $B$27:$E$27, 0)), 0) -> 0 | E38: =IFERROR(INDEX($B$28:$E$31, MATCH($N38, $B$27:$E$27, 0), MATCH(E$33, $B$27:$E$27, 0)), 0) -> 0 | F38: =IFERROR(INDEX($B$28:$E$31, MATCH($N38, $B$27:$E$27, 0), MATCH(F$33, $B$27:$E$27, 0)), 0) -> 0 | G38: =IFERROR(INDEX($B$28:$E$31, MATCH($N38, $B$27:$E$27, 0), MATCH(G$33, $B$27:$E$27, 0)), 0) -> 0 | H38: =IFERROR(INDEX($B$28:$E$31, MATCH($N38, $B$27:$E$27, 0), MATCH(H$33, $B$27:$E$27, 0)), 0) -> 0 | I38: =IFERROR(INDEX($B$28:$E$31, MATCH($N38, $B$27:$E$27, 0), MATCH(I$33, $B$27:$E$27, 0)), 0) -> 0 | ... M38: =IFERROR(INDEX($B$28:$E$31, MATCH($N38, $B$27:$E$27, 0), MATCH(M$33, $B$27:$E$27, 0)), 0) -> 0 | N38: U3X
A39: K1= | B39: =IFERROR(INDEX($B$28:$E$31, MATCH($N39, $B$27:$E$27, 0), MATCH(B$33, $B$27:$E$27, 0)), 0) -> 0 | C39: =IFERROR(INDEX($B$28:$E$31, MATCH($N39, $B$27:$E$27, 0), MATCH(C$33, $B$27:$E$27, 0)), 0) -> 0 | D39: =IFERROR(INDEX($B$28:$E$31, MATCH($N39, $B$27:$E$27, 0), MATCH(D$33, $B$27:$E$27, 0)), 0) -> 0 | E39: =IFERROR(INDEX($B$28:$E$31, MATCH($N39, $B$27:$E$27, 0), MATCH(E$33, $B$27:$E$27, 0)), 0) -> 0 | F39: =IFERROR(INDEX($B$28:$E$31, MATCH($N39, $B$27:$E$27, 0), MATCH(F$33, $B$27:$E$27, 0)), 0) -> 0 | G39: =IFERROR(INDEX($B$28:$E$31, MATCH($N39, $B$27:$E$27, 0), MATCH(G$33, $B$27:$E$27, 0)), 0) -> 0 | H39: =IFERROR(INDEX($B$28:$E$31, MATCH($N39, $B$27:$E$27, 0), MATCH(H$33, $B$27:$E$27, 0)), 0) -> 0 | I39: =IFERROR(INDEX($B$28:$E$31, MATCH($N39, $B$27:$E$27, 0), MATCH(I$33, $B$27:$E$27, 0)), 0) -> 0 | ... M39: =IFERROR(INDEX($B$28:$E$31, MATCH($N39, $B$27:$E$27, 0), MATCH(M$33, $B$27:$E$27, 0)), 0) -> 0 | N39: U3Y
B40: =IFERROR(INDEX($B$28:$E$31, MATCH($N40, $B$27:$E$27, 0), MATCH(B$33, $B$27:$E$27, 0)), 0) -> 0 | C40: =IFERROR(INDEX($B$28:$E$31, MATCH($N40, $B$27:$E$27, 0), MATCH(C$33, $B$27:$E$27, 0)), 0) -> 0 | D40: =IFERROR(INDEX($B$28:$E$31, MATCH($N40, $B$27:$E$27, 0), MATCH(D$33, $B$27:$E$27, 0)), 0) -> 0 | E40: =IFERROR(INDEX($B$28:$E$31, MATCH($N40, $B$27:$E$27, 0), MATCH(E$33, $B$27:$E$27, 0)), 0) -> 0 | F40: =IFERROR(INDEX($B$28:$E$31, MATCH($N40, $B$27:$E$27, 0), MATCH(F$33, $B$27:$E$27, 0)), 0) -> 0 | G40: =IFERROR(INDEX($B$28:$E$31, MATCH($N40, $B$27:$E$27, 0), MATCH(G$33, $B$27:$E$27, 0)), 0) -> 0 | H40: =IFERROR(INDEX($B$28:$E$31, MATCH($N40, $B$27:$E$27, 0), MATCH(H$33, $B$27:$E$27, 0)), 0) -> 0 | I40: =IFERROR(INDEX($B$28:$E$31, MATCH($N40, $B$27:$E$27, 0), MATCH(I$33, $B$27:$E$27, 0)), 0) -> 0 | ... M40: =IFERROR(INDEX($B$28:$E$31, MATCH($N40, $B$27:$E$27, 0), MATCH(M$33, $B$27:$E$27, 0)), 0) -> 0 | N40: U4X
B41: =IFERROR(INDEX($B$28:$E$31, MATCH($N41, $B$27:$E$27, 0), MATCH(B$33, $B$27:$E$27, 0)), 0) -> 0 | C41: =IFERROR(INDEX($B$28:$E$31, MATCH($N41, $B$27:$E$27, 0), MATCH(C$33, $B$27:$E$27, 0)), 0) -> 0 | D41: =IFERROR(INDEX($B$28:$E$31, MATCH($N41, $B$27:$E$27, 0), MATCH(D$33, $B$27:$E$27, 0)), 0) -> 0 | E41: =IFERROR(INDEX($B$28:$E$31, MATCH($N41, $B$27:$E$27, 0), MATCH(E$33, $B$27:$E$27, 0)), 0) -> 0 | F41: =IFERROR(INDEX($B$28:$E$31, MATCH($N41, $B$27:$E$27, 0), MATCH(F$33, $B$27:$E$27, 0)), 0) -> 0 | G41: =IFERROR(INDEX($B$28:$E$31, MATCH($N41, $B$27:$E$27, 0), MATCH(G$33, $B$27:$E$27, 0)), 0) -> 0 | H41: =IFERROR(INDEX($B$28:$E$31, MATCH($N41, $B$27:$E$27, 0), MATCH(H$33, $B$27:$E$27, 0)), 0) -> 0 | I41: =IFERROR(INDEX($B$28:$E$31, MATCH($N41, $B$27:$E$27, 0), MATCH(I$33, $B$27:$E$27, 0)), 0) -> 0 | ... M41: =IFERROR(INDEX($B$28:$E$31, MATCH($N41, $B$27:$E$27, 0), MATCH(M$33, $B$27:$E$27, 0)), 0) -> 0 | N41: U4Y
B42: =IFERROR(INDEX($B$28:$E$31, MATCH($N42, $B$27:$E$27, 0), MATCH(B$33, $B$27:$E$27, 0)), 0) -> 0 | C42: =IFERROR(INDEX($B$28:$E$31, MATCH($N42, $B$27:$E$27, 0), MATCH(C$33, $B$27:$E$27, 0)), 0) -> 0 | D42: =IFERROR(INDEX($B$28:$E$31, MATCH($N42, $B$27:$E$27, 0), MATCH(D$33, $B$27:$E$27, 0)), 0) -> 0 | E42: =IFERROR(INDEX($B$28:$E$31, MATCH($N42, $B$27:$E$27, 0), MATCH(E$33, $B$27:$E$27, 0)), 0) -> 0 | F42: =IFERROR(INDEX($B$28:$E$31, MATCH($N42, $B$27:$E$27, 0), MATCH(F$33, $B$27:$E$27, 0)), 0) -> 0 | G42: =IFERROR(INDEX($B$28:$E$31, MATCH($N42, $B$27:$E$27, 0), MATCH(G$33, $B$27:$E$27, 0)), 0) -> 0 | H42: =IFERROR(INDEX($B$28:$E$31, MATCH($N42, $B$27:$E$27, 0), MATCH(H$33, $B$27:$E$27, 0)), 0) -> 0 | I42: =IFERROR(INDEX($B$28:$E$31, MATCH($N42, $B$27:$E$27, 0), MATCH(I$33, $B$27:$E$27, 0)), 0) -> 0 | ... M42: =IFERROR(INDEX($B$28:$E$31, MATCH($N42, $B$27:$E$27, 0), MATCH(M$33, $B$27:$E$27, 0)), 0) -> 0 | N42: U5X
B43: =IFERROR(INDEX($B$28:$E$31, MATCH($N43, $B$27:$E$27, 0), MATCH(B$33, $B$27:$E$27, 0)), 0) -> 0 | C43: =IFERROR(INDEX($B$28:$E$31, MATCH($N43, $B$27:$E$27, 0), MATCH(C$33, $B$27:$E$27, 0)), 0) -> 0 | D43: =IFERROR(INDEX($B$28:$E$31, MATCH($N43, $B$27:$E$27, 0), MATCH(D$33, $B$27:$E$27, 0)), 0) -> 0 | E43: =IFERROR(INDEX($B$28:$E$31, MATCH($N43, $B$27:$E$27, 0), MATCH(E$33, $B$27:$E$27, 0)), 0) -> 0 | F43: =IFERROR(INDEX($B$28:$E$31, MATCH($N43, $B$27:$E$27, 0), MATCH(F$33, $B$27:$E$27, 0)), 0) -> 0 | G43: =IFERROR(INDEX($B$28:$E$31, MATCH($N43, $B$27:$E$27, 0), MATCH(G$33, $B$27:$E$27, 0)), 0) -> 0 | H43: =IFERROR(INDEX($B$28:$E$31, MATCH($N43, $B$27:$E$27, 0), MATCH(H$33, $B$27:$E$27, 0)), 0) -> 0 | I43: =IFERROR(INDEX($B$28:$E$31, MATCH($N43, $B$27:$E$27, 0), MATCH(I$33, $B$27:$E$27, 0)), 0) -> 0 | ... M43: =IFERROR(INDEX($B$28:$E$31, MATCH($N43, $B$27:$E$27, 0), MATCH(M$33, $B$27:$E$27, 0)), 0) -> 0 | N43: U5Y
B44: =IFERROR(INDEX($B$28:$E$31, MATCH($N44, $B$27:$E$27, 0), MATCH(B$33, $B$27:$E$27, 0)), 0) -> 0 | C44: =IFERROR(INDEX($B$28:$E$31, MATCH($N44, $B$27:$E$27, 0), MATCH(C$33, $B$27:$E$27, 0)), 0) -> 0 | D44: =IFERROR(INDEX($B$28:$E$31, MATCH($N44, $B$27:$E$27, 0), MATCH(D$33, $B$27:$E$27, 0)), 0) -> 0 | E44: =IFERROR(INDEX($B$28:$E$31, MATCH($N44, $B$27:$E$27, 0), MATCH(E$33, $B$27:$E$27, 0)), 0) -> 0 | F44: =IFERROR(INDEX($B$28:$E$31, MATCH($N44, $B$27:$E$27, 0), MATCH(F$33, $B$27:$E$27, 0)), 0) -> 0 | G44: =IFERROR(INDEX($B$28:$E$31, MATCH($N44, $B$27:$E$27, 0), MATCH(G$33, $B$27:$E$27, 0)), 0) -> 0 | H44: =IFERROR(INDEX($B$28:$E$31, MATCH($N44, $B$27:$E$27, 0), MATCH(H$33, $B$27:$E$27, 0)), 0) -> 0 | I44: =IFERROR(INDEX($B$28:$E$31, MATCH($N44, $B$27:$E$27, 0), MATCH(I$33, $B$27:$E$27, 0)), 0) -> 0 | ... M44: =IFERROR(INDEX($B$28:$E$31, MATCH($N44, $B$27:$E$27, 0), MATCH(M$33, $B$27:$E$27, 0)), 0) -> 0 | N44: U6X
B45: =IFERROR(INDEX($B$28:$E$31, MATCH($N45, $B$27:$E$27, 0), MATCH(B$33, $B$27:$E$27, 0)), 0) -> 0 | C45: =IFERROR(INDEX($B$28:$E$31, MATCH($N45, $B$27:$E$27, 0), MATCH(C$33, $B$27:$E$27, 0)), 0) -> 0 | D45: =IFERROR(INDEX($B$28:$E$31, MATCH($N45, $B$27:$E$27, 0), MATCH(D$33, $B$27:$E$27, 0)), 0) -> 0 | E45: =IFERROR(INDEX($B$28:$E$31, MATCH($N45, $B$27:$E$27, 0), MATCH(E$33, $B$27:$E$27, 0)), 0) -> 0 | F45: =IFERROR(INDEX($B$28:$E$31, MATCH($N45, $B$27:$E$27, 0), MATCH(F$33, $B$27:$E$27, 0)), 0) -> 0 | G45: =IFERROR(INDEX($B$28:$E$31, MATCH($N45, $B$27:$E$27, 0), MATCH(G$33, $B$27:$E$27, 0)), 0) -> 0 | H45: =IFERROR(INDEX($B$28:$E$31, MATCH($N45, $B$27:$E$27, 0), MATCH(H$33, $B$27:$E$27, 0)), 0) -> 0 | I45: =IFERROR(INDEX($B$28:$E$31, MATCH($N45, $B$27:$E$27, 0), MATCH(I$33, $B$27:$E$27, 0)), 0) -> 0 | ... M45: =IFERROR(INDEX($B$28:$E$31, MATCH($N45, $B$27:$E$27, 0), MATCH(M$33, $B$27:$E$27, 0)), 0) -> 0 | N45: U6Y
...

Sheet MANUAL_ISOSTATICA_3R (4)
A1: PLANTILLA MANUAL - CASO ISOSTÁTICO (HASTA 6 NODOS Y 8 BARRAS - CÁTEDRA ING. ULIANOV)
A2: Cátedra: Análisis Estructural II | Ing. Ulianov Cuba Valencia | Plantilla 100% Automatizada con Capacidad hasta 6 Nodos y 8 Barras
B4: BARRA | C4: INICIO (cm) | E4: FIN (cm) | G4: DX (cm) | H4: DY (cm) | I4: L (cm) | J4: Cx | K4: Cy | L4: A (cm²) | M4: E (Kgf/cm²) | N4: AE/L (Kgf/cm) | P4: COORDENADAS, CONDICIONES DE APOYO Y CARGAS NODALES (HASTA 6 NODOS)
C5: X | D5: Y | E5: X | F5: Y | P5: NUDO | Q5: X (cm) | R5: Y (cm) | S5: TIPO APOYO | T5: Rx | U5: Ry | V5: Px (Kgf) | W5: Py (Kgf)
B6: 1 | C6: =IF(C17="","", IFERROR(VLOOKUP(C17, $P$6:$W$11, 2, FALSE), "")) -> 0 | D6: =IF(C17="","", IFERROR(VLOOKUP(C17, $P$6:$W$11, 3, FALSE), "")) -> 0 | E6: =IF(F17="","", IFERROR(VLOOKUP(F17, $P$6:$W$11, 2, FALSE), "")) -> 200 | F6: =IF(F17="","", IFERROR(VLOOKUP(F17, $P$6:$W$11, 3, FALSE), "")) -> 600 | G6: =IF(OR(C6="",E6=""), "", E6-C6) -> 200 | H6: =IF(OR(D6="",F6=""), "", F6-D6) -> 600 | I6: =IF(OR(G6="",H6=""), "", SQRT(G6^2+H6^2)) -> 632.45553 | J6: =IF(OR(I6="",I6=0), "", G6/I6) -> 0.31622777 | K6: =IF(OR(I6="",I6=0), "", H6/I6) -> 0.9486833 | L6: =IF(C17="","", 20) -> 20 | M6: =IF(C17="","", 150000) -> 150000 | N6: =IF(OR(I6="",I6=0,L6="",M6=""), 0, (L6*M6)/I6) -> 4743.4165 | P6: 1 | Q6: 800 | R6: 800 | S6: Libre | T6: =IF(Q6="","", IF(LEFT(UPPER(TRIM(S6)),4)="FIJO", 1, IF(OR(UPPER(TRIM(S6))="MOVIL X", UPPER(TRIM(S6))="MÓVIL X", UPPER(TRIM(S6))="RODILLO X"), 1, 0))) -> 0 | U6: =IF(Q6="","", IF(LEFT(UPPER(TRIM(S6)),4)="FIJO", 1, IF(OR(UPPER(TRIM(S6))="MOVIL Y", UPPER(TRIM(S6))="MÓVIL Y", UPPER(TRIM(S6))="RODILLO Y", UPPER(TRIM(S6))="MOVIL", UPPER(TRIM(S6))="MÓVIL"), 1, 0))) -> 0 | V6: 1000 | W6: -2000
B7: 2 | C7: =IF(C18="","", IFERROR(VLOOKUP(C18, $P$6:$W$11, 2, FALSE), "")) -> 1000 | D7: =IF(C18="","", IFERROR(VLOOKUP(C18, $P$6:$W$11, 3, FALSE), "")) -> 0 | E7: =IF(F18="","", IFERROR(VLOOKUP(F18, $P$6:$W$11, 2, FALSE), "")) -> 0 | F7: =IF(F18="","", IFERROR(VLOOKUP(F18, $P$6:$W$11, 3, FALSE), "")) -> 0 | G7: =IF(OR(C7="",E7=""), "", E7-C7) -> -1000 | H7: =IF(OR(D7="",F7=""), "", F7-D7) -> 0 | I7: =IF(OR(G7="",H7=""), "", SQRT(G7^2+H7^2)) -> 1000 | J7: =IF(OR(I7="",I7=0), "", G7/I7) -> -1 | K7: =IF(OR(I7="",I7=0), "", H7/I7) -> 0 | L7: =IF(C18="","", 20) -> 20 | M7: =IF(C18="","", 150000) -> 150000 | N7: =IF(OR(I7="",I7=0,L7="",M7=""), 0, (L7*M7)/I7) -> 3000 | P7: 2 | Q7: 200 | R7: 600 | S7: Libre | T7: =IF(Q7="","", IF(LEFT(UPPER(TRIM(S7)),4)="FIJO", 1, IF(OR(UPPER(TRIM(S7))="MOVIL X", UPPER(TRIM(S7))="MÓVIL X", UPPER(TRIM(S7))="RODILLO X"), 1, 0))) -> 0 | U7: =IF(Q7="","", IF(LEFT(UPPER(TRIM(S7)),4)="FIJO", 1, IF(OR(UPPER(TRIM(S7))="MOVIL Y", UPPER(TRIM(S7))="MÓVIL Y", UPPER(TRIM(S7))="RODILLO Y", UPPER(TRIM(S7))="MOVIL", UPPER(TRIM(S7))="MÓVIL"), 1, 0))) -> 0 | V7: 2000 | W7: -1000
B8: 3 | C8: =IF(C19="","", IFERROR(VLOOKUP(C19, $P$6:$W$11, 2, FALSE), "")) -> 800 | D8: =IF(C19="","", IFERROR(VLOOKUP(C19, $P$6:$W$11, 3, FALSE), "")) -> 800 | E8: =IF(F19="","", IFERROR(VLOOKUP(F19, $P$6:$W$11, 2, FALSE), "")) -> 1000 | F8: =IF(F19="","", IFERROR(VLOOKUP(F19, $P$6:$W$11, 3, FALSE), "")) -> 0 | G8: =IF(OR(C8="",E8=""), "", E8-C8) -> 200 | H8: =IF(OR(D8="",F8=""), "", F8-D8) -> -800 | I8: =IF(OR(G8="",H8=""), "", SQRT(G8^2+H8^2)) -> 824.62113 | J8: =IF(OR(I8="",I8=0), "", G8/I8) -> 0.24253563 | K8: =IF(OR(I8="",I8=0), "", H8/I8) -> -0.9701425 | L8: =IF(C19="","", 20) -> 20 | M8: =IF(C19="","", 150000) -> 150000 | N8: =IF(OR(I8="",I8=0,L8="",M8=""), 0, (L8*M8)/I8) -> 3638.0344 | P8: 3 | Q8: 0 | R8: 0 | S8: Móvil Y | T8: =IF(Q8="","", IF(LEFT(UPPER(TRIM(S8)),4)="FIJO", 1, IF(OR(UPPER(TRIM(S8))="MOVIL X", UPPER(TRIM(S8))="MÓVIL X", UPPER(TRIM(S8))="RODILLO X"), 1, 0))) -> 0 | U8: =IF(Q8="","", IF(LEFT(UPPER(TRIM(S8)),4)="FIJO", 1, IF(OR(UPPER(TRIM(S8))="MOVIL Y", UPPER(TRIM(S8))="MÓVIL Y", UPPER(TRIM(S8))="RODILLO Y", UPPER(TRIM(S8))="MOVIL", UPPER(TRIM(S8))="MÓVIL"), 1, 0))) -> 1 | V8: 0 | W8: 0
B9: 4 | C9: =IF(C20="","", IFERROR(VLOOKUP(C20, $P$6:$W$11, 2, FALSE), "")) -> 200 | D9: =IF(C20="","", IFERROR(VLOOKUP(C20, $P$6:$W$11, 3, FALSE), "")) -> 600 | E9: =IF(F20="","", IFERROR(VLOOKUP(F20, $P$6:$W$11, 2, FALSE), "")) -> 1000 | F9: =IF(F20="","", IFERROR(VLOOKUP(F20, $P$6:$W$11, 3, FALSE), "")) -> 0 | G9: =IF(OR(C9="",E9=""), "", E9-C9) -> 800 | H9: =IF(OR(D9="",F9=""), "", F9-D9) -> -600 | I9: =IF(OR(G9="",H9=""), "", SQRT(G9^2+H9^2)) -> 1000 | J9: =IF(OR(I9="",I9=0), "", G9/I9) -> 0.8 | K9: =IF(OR(I9="",I9=0), "", H9/I9) -> -0.6 | L9: =IF(C20="","", 20) -> 20 | M9: =IF(C20="","", 150000) -> 150000 | N9: =IF(OR(I9="",I9=0,L9="",M9=""), 0, (L9*M9)/I9) -> 3000 | P9: 4 | Q9: 1000 | R9: 0 | S9: Fijo | T9: =IF(Q9="","", IF(LEFT(UPPER(TRIM(S9)),4)="FIJO", 1, IF(OR(UPPER(TRIM(S9))="MOVIL X", UPPER(TRIM(S9))="MÓVIL X", UPPER(TRIM(S9))="RODILLO X"), 1, 0))) -> 1 | U9: =IF(Q9="","", IF(LEFT(UPPER(TRIM(S9)),4)="FIJO", 1, IF(OR(UPPER(TRIM(S9))="MOVIL Y", UPPER(TRIM(S9))="MÓVIL Y", UPPER(TRIM(S9))="RODILLO Y", UPPER(TRIM(S9))="MOVIL", UPPER(TRIM(S9))="MÓVIL"), 1, 0))) -> 1 | V9: 0 | W9: 0
B10: 5 | C10: =IF(C21="","", IFERROR(VLOOKUP(C21, $P$6:$W$11, 2, FALSE), "")) -> 200 | D10: =IF(C21="","", IFERROR(VLOOKUP(C21, $P$6:$W$11, 3, FALSE), "")) -> 600 | E10: =IF(F21="","", IFERROR(VLOOKUP(F21, $P$6:$W$11, 2, FALSE), "")) -> 800 | F10: =IF(F21="","", IFERROR(VLOOKUP(F21, $P$6:$W$11, 3, FALSE), "")) -> 800 | G10: =IF(OR(C10="",E10=""), "", E10-C10) -> 600 | H10: =IF(OR(D10="",F10=""), "", F10-D10) -> 200 | I10: =IF(OR(G10="",H10=""), "", SQRT(G10^2+H10^2)) -> 632.45553 | J10: =IF(OR(I10="",I10=0), "", G10/I10) -> 0.9486833 | K10: =IF(OR(I10="",I10=0), "", H10/I10) -> 0.31622777 | L10: =IF(C21="","", 20) -> 20 | M10: =IF(C21="","", 150000) -> 150000 | N10: =IF(OR(I10="",I10=0,L10="",M10=""), 0, (L10*M10)/I10) -> 4743.4165 | P10: 5 | T10: =IF(Q10="","", IF(LEFT(UPPER(TRIM(S10)),4)="FIJO", 1, IF(OR(UPPER(TRIM(S10))="MOVIL X", UPPER(TRIM(S10))="MÓVIL X", UPPER(TRIM(S10))="RODILLO X"), 1, 0))) | U10: =IF(Q10="","", IF(LEFT(UPPER(TRIM(S10)),4)="FIJO", 1, IF(OR(UPPER(TRIM(S10))="MOVIL Y", UPPER(TRIM(S10))="MÓVIL Y", UPPER(TRIM(S10))="RODILLO Y", UPPER(TRIM(S10))="MOVIL", UPPER(TRIM(S10))="MÓVIL"), 1, 0)))
B11: 6 | C11: =IF(C22="","", IFERROR(VLOOKUP(C22, $P$6:$W$11, 2, FALSE), "")) | D11: =IF(C22="","", IFERROR(VLOOKUP(C22, $P$6:$W$11, 3, FALSE), "")) | E11: =IF(F22="","", IFERROR(VLOOKUP(F22, $P$6:$W$11, 2, FALSE), "")) | F11: =IF(F22="","", IFERROR(VLOOKUP(F22, $P$6:$W$11, 3, FALSE), "")) | G11: =IF(OR(C11="",E11=""), "", E11-C11) | H11: =IF(OR(D11="",F11=""), "", F11-D11) | I11: =IF(OR(G11="",H11=""), "", SQRT(G11^2+H11^2)) | J11: =IF(OR(I11="",I11=0), "", G11/I11) | K11: =IF(OR(I11="",I11=0), "", H11/I11) | L11: =IF(C22="","", 10) | M11: =IF(C22="","", 2100000) | N11: =IF(OR(I11="",I11=0,L11="",M11=""), 0, (L11*M11)/I11) -> 0 | P11: 6 | T11: =IF(Q11="","", IF(LEFT(UPPER(TRIM(S11)),4)="FIJO", 1, IF(OR(UPPER(TRIM(S11))="MOVIL X", UPPER(TRIM(S11))="MÓVIL X", UPPER(TRIM(S11))="RODILLO X"), 1, 0))) | U11: =IF(Q11="","", IF(LEFT(UPPER(TRIM(S11)),4)="FIJO", 1, IF(OR(UPPER(TRIM(S11))="MOVIL Y", UPPER(TRIM(S11))="MÓVIL Y", UPPER(TRIM(S11))="RODILLO Y", UPPER(TRIM(S11))="MOVIL", UPPER(TRIM(S11))="MÓVIL"), 1, 0)))
B12: 7 | C12: =IF(C23="","", IFERROR(VLOOKUP(C23, $P$6:$W$11, 2, FALSE), "")) | D12: =IF(C23="","", IFERROR(VLOOKUP(C23, $P$6:$W$11, 3, FALSE), "")) | E12: =IF(F23="","", IFERROR(VLOOKUP(F23, $P$6:$W$11, 2, FALSE), "")) | F12: =IF(F23="","", IFERROR(VLOOKUP(F23, $P$6:$W$11, 3, FALSE), "")) | G12: =IF(OR(C12="",E12=""), "", E12-C12) | H12: =IF(OR(D12="",F12=""), "", F12-D12) | I12: =IF(OR(G12="",H12=""), "", SQRT(G12^2+H12^2)) | J12: =IF(OR(I12="",I12=0), "", G12/I12) | K12: =IF(OR(I12="",I12=0), "", H12/I12) | L12: =IF(C23="","", 10) | M12: =IF(C23="","", 2100000) | N12: =IF(OR(I12="",I12=0,L12="",M12=""), 0, (L12*M12)/I12) -> 0
B13: 8 | C13: =IF(C24="","", IFERROR(VLOOKUP(C24, $P$6:$W$11, 2, FALSE), "")) | D13: =IF(C24="","", IFERROR(VLOOKUP(C24, $P$6:$W$11, 3, FALSE), "")) | E13: =IF(F24="","", IFERROR(VLOOKUP(F24, $P$6:$W$11, 2, FALSE), "")) | F13: =IF(F24="","", IFERROR(VLOOKUP(F24, $P$6:$W$11, 3, FALSE), "")) | G13: =IF(OR(C13="",E13=""), "", E13-C13) | H13: =IF(OR(D13="",F13=""), "", F13-D13) | I13: =IF(OR(G13="",H13=""), "", SQRT(G13^2+H13^2)) | J13: =IF(OR(I13="",I13=0), "", G13/I13) | K13: =IF(OR(I13="",I13=0), "", H13/I13) | L13: =IF(C24="","", 10) | M13: =IF(C24="","", 2100000) | N13: =IF(OR(I13="",I13=0,L13="",M13=""), 0, (L13*M13)/I13) -> 0
B15: CONECTIVIDAD DE BARRAS Y GRADOS DE LIBERTAD ASOCIADOS:
B16: BARRA | C16: NUDO INICIO | D16: UX | E16: UY | F16: NUDO FIN | G16: UX | H16: UY | S16: Móvil Y
B17: 1 | C17: 3 | D17: =IF(C17="","", "U" & C17 & "X") -> U3X | E17: =IF(C17="","", "U" & C17 & "Y") -> U3Y | F17: 2 | G17: =IF(F17="","", "U" & F17 & "X") -> U2X | H17: =IF(F17="","", "U" & F17 & "Y") -> U2Y | S17: Fijo
B18: 2 | C18: 4 | D18: =IF(C18="","", "U" & C18 & "X") -> U4X | E18: =IF(C18="","", "U" & C18 & "Y") -> U4Y | F18: 3 | G18: =IF(F18="","", "U" & F18 & "X") -> U3X | H18: =IF(F18="","", "U" & F18 & "Y") -> U3Y | S18: Libre
B19: 3 | C19: 1 | D19: =IF(C19="","", "U" & C19 & "X") -> U1X | E19: =IF(C19="","", "U" & C19 & "Y") -> U1Y | F19: 4 | G19: =IF(F19="","", "U" & F19 & "X") -> U4X | H19: =IF(F19="","", "U" & F19 & "Y") -> U4Y | S19: Libre
B20: 4 | C20: 2 | D20: =IF(C20="","", "U" & C20 & "X") -> U2X | E20: =IF(C20="","", "U" & C20 & "Y") -> U2Y | F20: 4 | G20: =IF(F20="","", "U" & F20 & "X") -> U4X | H20: =IF(F20="","", "U" & F20 & "Y") -> U4Y | S20: Libre
B21: 5 | C21: 2 | D21: =IF(C21="","", "U" & C21 & "X") -> U2X | E21: =IF(C21="","", "U" & C21 & "Y") -> U2Y | F21: 1 | G21: =IF(F21="","", "U" & F21 & "X") -> U1X | H21: =IF(F21="","", "U" & F21 & "Y") -> U1Y | S21: Libre
B22: 6 | D22: =IF(C22="","", "U" & C22 & "X") | E22: =IF(C22="","", "U" & C22 & "Y") | G22: =IF(F22="","", "U" & F22 & "X") | H22: =IF(F22="","", "U" & F22 & "Y")
B23: 7 | D23: =IF(C23="","", "U" & C23 & "X") | E23: =IF(C23="","", "U" & C23 & "Y") | G23: =IF(F23="","", "U" & F23 & "X") | H23: =IF(F23="","", "U" & F23 & "Y")
B24: 8 | D24: =IF(C24="","", "U" & C24 & "X") | E24: =IF(C24="","", "U" & C24 & "Y") | G24: =IF(F24="","", "U" & F24 & "X") | H24: =IF(F24="","", "U" & F24 & "Y")
A27: k1= | B27: =IF(D17="","-",D17) -> U3X | C27: =IF(E17="","-",E17) -> U3Y | D27: =IF(G17="","-",G17) -> U2X | E27: =IF(H17="","-",H17) -> U2Y
B28: =IF(N6=0, 0, N6*J6*J6) -> 474.34165 | C28: =IF(N6=0, 0, N6*J6*K6) -> 1423.0249 | D28: =IF(N6=0, 0, -N6*J6*J6) -> -474.34165 | E28: =IF(N6=0, 0, -N6*J6*K6) -> -1423.0249 | F28: =IF(D17="","-",D17) -> U3X
B29: =IF(N6=0, 0, N6*J6*K6) -> 1423.0249 | C29: =IF(N6=0, 0, N6*K6*K6) -> 4269.0748 | D29: =IF(N6=0, 0, -N6*J6*K6) -> -1423.0249 | E29: =IF(N6=0, 0, -N6*K6*K6) -> -4269.0748 | F29: =IF(E17="","-",E17) -> U3Y
B30: =IF(N6=0, 0, -N6*J6*J6) -> -474.34165 | C30: =IF(N6=0, 0, -N6*J6*K6) -> -1423.0249 | D30: =IF(N6=0, 0, N6*J6*J6) -> 474.34165 | E30: =IF(N6=0, 0, N6*J6*K6) -> 1423.0249 | F30: =IF(G17="","-",G17) -> U2X
B31: =IF(N6=0, 0, -N6*J6*K6) -> -1423.0249 | C31: =IF(N6=0, 0, -N6*K6*K6) -> -4269.0748 | D31: =IF(N6=0, 0, N6*J6*K6) -> 1423.0249 | E31: =IF(N6=0, 0, N6*K6*K6) -> 4269.0748 | F31: =IF(H17="","-",H17) -> U2Y
B33: U1X | C33: U1Y | D33: U2X | E33: U2Y | F33: U3X | G33: U3Y | H33: U4X | I33: U4Y | J33: U5X | K33: U5Y | L33: U6X | M33: U6Y
B34: =IFERROR(INDEX($B$28:$E$31, MATCH($N34, $B$27:$E$27, 0), MATCH(B$33, $B$27:$E$27, 0)), 0) -> 0 | C34: =IFERROR(INDEX($B$28:$E$31, MATCH($N34, $B$27:$E$27, 0), MATCH(C$33, $B$27:$E$27, 0)), 0) -> 0 | D34: =IFERROR(INDEX($B$28:$E$31, MATCH($N34, $B$27:$E$27, 0), MATCH(D$33, $B$27:$E$27, 0)), 0) -> 0 | E34: =IFERROR(INDEX($B$28:$E$31, MATCH($N34, $B$27:$E$27, 0), MATCH(E$33, $B$27:$E$27, 0)), 0) -> 0 | F34: =IFERROR(INDEX($B$28:$E$31, MATCH($N34, $B$27:$E$27, 0), MATCH(F$33, $B$27:$E$27, 0)), 0) -> 0 | G34: =IFERROR(INDEX($B$28:$E$31, MATCH($N34, $B$27:$E$27, 0), MATCH(G$33, $B$27:$E$27, 0)), 0) -> 0 | H34: =IFERROR(INDEX($B$28:$E$31, MATCH($N34, $B$27:$E$27, 0), MATCH(H$33, $B$27:$E$27, 0)), 0) -> 0 | I34: =IFERROR(INDEX($B$28:$E$31, MATCH($N34, $B$27:$E$27, 0), MATCH(I$33, $B$27:$E$27, 0)), 0) -> 0 | ... M34: =IFERROR(INDEX($B$28:$E$31, MATCH($N34, $B$27:$E$27, 0), MATCH(M$33, $B$27:$E$27, 0)), 0) -> 0 | N34: U1X
B35: =IFERROR(INDEX($B$28:$E$31, MATCH($N35, $B$27:$E$27, 0), MATCH(B$33, $B$27:$E$27, 0)), 0) -> 0 | C35: =IFERROR(INDEX($B$28:$E$31, MATCH($N35, $B$27:$E$27, 0), MATCH(C$33, $B$27:$E$27, 0)), 0) -> 0 | D35: =IFERROR(INDEX($B$28:$E$31, MATCH($N35, $B$27:$E$27, 0), MATCH(D$33, $B$27:$E$27, 0)), 0) -> 0 | E35: =IFERROR(INDEX($B$28:$E$31, MATCH($N35, $B$27:$E$27, 0), MATCH(E$33, $B$27:$E$27, 0)), 0) -> 0 | F35: =IFERROR(INDEX($B$28:$E$31, MATCH($N35, $B$27:$E$27, 0), MATCH(F$33, $B$27:$E$27, 0)), 0) -> 0 | G35: =IFERROR(INDEX($B$28:$E$31, MATCH($N35, $B$27:$E$27, 0), MATCH(G$33, $B$27:$E$27, 0)), 0) -> 0 | H35: =IFERROR(INDEX($B$28:$E$31, MATCH($N35, $B$27:$E$27, 0), MATCH(H$33, $B$27:$E$27, 0)), 0) -> 0 | I35: =IFERROR(INDEX($B$28:$E$31, MATCH($N35, $B$27:$E$27, 0), MATCH(I$33, $B$27:$E$27, 0)), 0) -> 0 | ... M35: =IFERROR(INDEX($B$28:$E$31, MATCH($N35, $B$27:$E$27, 0), MATCH(M$33, $B$27:$E$27, 0)), 0) -> 0 | N35: U1Y
B36: =IFERROR(INDEX($B$28:$E$31, MATCH($N36, $B$27:$E$27, 0), MATCH(B$33, $B$27:$E$27, 0)), 0) -> 0 | C36: =IFERROR(INDEX($B$28:$E$31, MATCH($N36, $B$27:$E$27, 0), MATCH(C$33, $B$27:$E$27, 0)), 0) -> 0 | D36: =IFERROR(INDEX($B$28:$E$31, MATCH($N36, $B$27:$E$27, 0), MATCH(D$33, $B$27:$E$27, 0)), 0) -> 474.34165 | E36: =IFERROR(INDEX($B$28:$E$31, MATCH($N36, $B$27:$E$27, 0), MATCH(E$33, $B$27:$E$27, 0)), 0) -> 1423.0249 | F36: =IFERROR(INDEX($B$28:$E$31, MATCH($N36, $B$27:$E$27, 0), MATCH(F$33, $B$27:$E$27, 0)), 0) -> -474.34165 | G36: =IFERROR(INDEX($B$28:$E$31, MATCH($N36, $B$27:$E$27, 0), MATCH(G$33, $B$27:$E$27, 0)), 0) -> -1423.0249 | H36: =IFERROR(INDEX($B$28:$E$31, MATCH($N36, $B$27:$E$27, 0), MATCH(H$33, $B$27:$E$27, 0)), 0) -> 0 | I36: =IFERROR(INDEX($B$28:$E$31, MATCH($N36, $B$27:$E$27, 0), MATCH(I$33, $B$27:$E$27, 0)), 0) -> 0 | ... M36: =IFERROR(INDEX($B$28:$E$31, MATCH($N36, $B$27:$E$27, 0), MATCH(M$33, $B$27:$E$27, 0)), 0) -> 0 | N36: U2X
B37: =IFERROR(INDEX($B$28:$E$31, MATCH($N37, $B$27:$E$27, 0), MATCH(B$33, $B$27:$E$27, 0)), 0) -> 0 | C37: =IFERROR(INDEX($B$28:$E$31, MATCH($N37, $B$27:$E$27, 0), MATCH(C$33, $B$27:$E$27, 0)), 0) -> 0 | D37: =IFERROR(INDEX($B$28:$E$31, MATCH($N37, $B$27:$E$27, 0), MATCH(D$33, $B$27:$E$27, 0)), 0) -> 1423.0249 | E37: =IFERROR(INDEX($B$28:$E$31, MATCH($N37, $B$27:$E$27, 0), MATCH(E$33, $B$27:$E$27, 0)), 0) -> 4269.0748 | F37: =IFERROR(INDEX($B$28:$E$31, MATCH($N37, $B$27:$E$27, 0), MATCH(F$33, $B$27:$E$27, 0)), 0) -> -1423.0249 | G37: =IFERROR(INDEX($B$28:$E$31, MATCH($N37, $B$27:$E$27, 0), MATCH(G$33, $B$27:$E$27, 0)), 0) -> -4269.0748 | H37: =IFERROR(INDEX($B$28:$E$31, MATCH($N37, $B$27:$E$27, 0), MATCH(H$33, $B$27:$E$27, 0)), 0) -> 0 | I37: =IFERROR(INDEX($B$28:$E$31, MATCH($N37, $B$27:$E$27, 0), MATCH(I$33, $B$27:$E$27, 0)), 0) -> 0 | ... M37: =IFERROR(INDEX($B$28:$E$31, MATCH($N37, $B$27:$E$27, 0), MATCH(M$33, $B$27:$E$27, 0)), 0) -> 0 | N37: U2Y
B38: =IFERROR(INDEX($B$28:$E$31, MATCH($N38, $B$27:$E$27, 0), MATCH(B$33, $B$27:$E$27, 0)), 0) -> 0 | C38: =IFERROR(INDEX($B$28:$E$31, MATCH($N38, $B$27:$E$27, 0), MATCH(C$33, $B$27:$E$27, 0)), 0) -> 0 | D38: =IFERROR(INDEX($B$28:$E$31, MATCH($N38, $B$27:$E$27, 0), MATCH(D$33, $B$27:$E$27, 0)), 0) -> -474.34165 | E38: =IFERROR(INDEX($B$28:$E$31, MATCH($N38, $B$27:$E$27, 0), MATCH(E$33, $B$27:$E$27, 0)), 0) -> -1423.0249 | F38: =IFERROR(INDEX($B$28:$E$31, MATCH($N38, $B$27:$E$27, 0), MATCH(F$33, $B$27:$E$27, 0)), 0) -> 474.34165 | G38: =IFERROR(INDEX($B$28:$E$31, MATCH($N38, $B$27:$E$27, 0), MATCH(G$33, $B$27:$E$27, 0)), 0) -> 1423.0249 | H38: =IFERROR(INDEX($B$28:$E$31, MATCH($N38, $B$27:$E$27, 0), MATCH(H$33, $B$27:$E$27, 0)), 0) -> 0 | I38: =IFERROR(INDEX($B$28:$E$31, MATCH($N38, $B$27:$E$27, 0), MATCH(I$33, $B$27:$E$27, 0)), 0) -> 0 | ... M38: =IFERROR(INDEX($B$28:$E$31, MATCH($N38, $B$27:$E$27, 0), MATCH(M$33, $B$27:$E$27, 0)), 0) -> 0 | N38: U3X
A39: K1= | B39: =IFERROR(INDEX($B$28:$E$31, MATCH($N39, $B$27:$E$27, 0), MATCH(B$33, $B$27:$E$27, 0)), 0) -> 0 | C39: =IFERROR(INDEX($B$28:$E$31, MATCH($N39, $B$27:$E$27, 0), MATCH(C$33, $B$27:$E$27, 0)), 0) -> 0 | D39: =IFERROR(INDEX($B$28:$E$31, MATCH($N39, $B$27:$E$27, 0), MATCH(D$33, $B$27:$E$27, 0)), 0) -> -1423.0249 | E39: =IFERROR(INDEX($B$28:$E$31, MATCH($N39, $B$27:$E$27, 0), MATCH(E$33, $B$27:$E$27, 0)), 0) -> -4269.0748 | F39: =IFERROR(INDEX($B$28:$E$31, MATCH($N39, $B$27:$E$27, 0), MATCH(F$33, $B$27:$E$27, 0)), 0) -> 1423.0249 | G39: =IFERROR(INDEX($B$28:$E$31, MATCH($N39, $B$27:$E$27, 0), MATCH(G$33, $B$27:$E$27, 0)), 0) -> 4269.0748 | H39: =IFERROR(INDEX($B$28:$E$31, MATCH($N39, $B$27:$E$27, 0), MATCH(H$33, $B$27:$E$27, 0)), 0) -> 0 | I39: =IFERROR(INDEX($B$28:$E$31, MATCH($N39, $B$27:$E$27, 0), MATCH(I$33, $B$27:$E$27, 0)), 0) -> 0 | ... M39: =IFERROR(INDEX($B$28:$E$31, MATCH($N39, $B$27:$E$27, 0), MATCH(M$33, $B$27:$E$27, 0)), 0) -> 0 | N39: U3Y
B40: =IFERROR(INDEX($B$28:$E$31, MATCH($N40, $B$27:$E$27, 0), MATCH(B$33, $B$27:$E$27, 0)), 0) -> 0 | C40: =IFERROR(INDEX($B$28:$E$31, MATCH($N40, $B$27:$E$27, 0), MATCH(C$33, $B$27:$E$27, 0)), 0) -> 0 | D40: =IFERROR(INDEX($B$28:$E$31, MATCH($N40, $B$27:$E$27, 0), MATCH(D$33, $B$27:$E$27, 0)), 0) -> 0 | E40: =IFERROR(INDEX($B$28:$E$31, MATCH($N40, $B$27:$E$27, 0), MATCH(E$33, $B$27:$E$27, 0)), 0) -> 0 | F40: =IFERROR(INDEX($B$28:$E$31, MATCH($N40, $B$27:$E$27, 0), MATCH(F$33, $B$27:$E$27, 0)), 0) -> 0 | G40: =IFERROR(INDEX($B$28:$E$31, MATCH($N40, $B$27:$E$27, 0), MATCH(G$33, $B$27:$E$27, 0)), 0) -> 0 | H40: =IFERROR(INDEX($B$28:$E$31, MATCH($N40, $B$27:$E$27, 0), MATCH(H$33, $B$27:$E$27, 0)), 0) -> 0 | I40: =IFERROR(INDEX($B$28:$E$31, MATCH($N40, $B$27:$E$27, 0), MATCH(I$33, $B$27:$E$27, 0)), 0) -> 0 | ... M40: =IFERROR(INDEX($B$28:$E$31, MATCH($N40, $B$27:$E$27, 0), MATCH(M$33, $B$27:$E$27, 0)), 0) -> 0 | N40: U4X
B41: =IFERROR(INDEX($B$28:$E$31, MATCH($N41, $B$27:$E$27, 0), MATCH(B$33, $B$27:$E$27, 0)), 0) -> 0 | C41: =IFERROR(INDEX($B$28:$E$31, MATCH($N41, $B$27:$E$27, 0), MATCH(C$33, $B$27:$E$27, 0)), 0) -> 0 | D41: =IFERROR(INDEX($B$28:$E$31, MATCH($N41, $B$27:$E$27, 0), MATCH(D$33, $B$27:$E$27, 0)), 0) -> 0 | E41: =IFERROR(INDEX($B$28:$E$31, MATCH($N41, $B$27:$E$27, 0), MATCH(E$33, $B$27:$E$27, 0)), 0) -> 0 | F41: =IFERROR(INDEX($B$28:$E$31, MATCH($N41, $B$27:$E$27, 0), MATCH(F$33, $B$27:$E$27, 0)), 0) -> 0 | G41: =IFERROR(INDEX($B$28:$E$31, MATCH($N41, $B$27:$E$27, 0), MATCH(G$33, $B$27:$E$27, 0)), 0) -> 0 | H41: =IFERROR(INDEX($B$28:$E$31, MATCH($N41, $B$27:$E$27, 0), MATCH(H$33, $B$27:$E$27, 0)), 0) -> 0 | I41: =IFERROR(INDEX($B$28:$E$31, MATCH($N41, $B$27:$E$27, 0), MATCH(I$33, $B$27:$E$27, 0)), 0) -> 0 | ... M41: =IFERROR(INDEX($B$28:$E$31, MATCH($N41, $B$27:$E$27, 0), MATCH(M$33, $B$27:$E$27, 0)), 0) -> 0 | N41: U4Y
B42: =IFERROR(INDEX($B$28:$E$31, MATCH($N42, $B$27:$E$27, 0), MATCH(B$33, $B$27:$E$27, 0)), 0) -> 0 | C42: =IFERROR(INDEX($B$28:$E$31, MATCH($N42, $B$27:$E$27, 0), MATCH(C$33, $B$27:$E$27, 0)), 0) -> 0 | D42: =IFERROR(INDEX($B$28:$E$31, MATCH($N42, $B$27:$E$27, 0), MATCH(D$33, $B$27:$E$27, 0)), 0) -> 0 | E42: =IFERROR(INDEX($B$28:$E$31, MATCH($N42, $B$27:$E$27, 0), MATCH(E$33, $B$27:$E$27, 0)), 0) -> 0 | F42: =IFERROR(INDEX($B$28:$E$31, MATCH($N42, $B$27:$E$27, 0), MATCH(F$33, $B$27:$E$27, 0)), 0) -> 0 | G42: =IFERROR(INDEX($B$28:$E$31, MATCH($N42, $B$27:$E$27, 0), MATCH(G$33, $B$27:$E$27, 0)), 0) -> 0 | H42: =IFERROR(INDEX($B$28:$E$31, MATCH($N42, $B$27:$E$27, 0), MATCH(H$33, $B$27:$E$27, 0)), 0) -> 0 | I42: =IFERROR(INDEX($B$28:$E$31, MATCH($N42, $B$27:$E$27, 0), MATCH(I$33, $B$27:$E$27, 0)), 0) -> 0 | ... M42: =IFERROR(INDEX($B$28:$E$31, MATCH($N42, $B$27:$E$27, 0), MATCH(M$33, $B$27:$E$27, 0)), 0) -> 0 | N42: U5X
B43: =IFERROR(INDEX($B$28:$E$31, MATCH($N43, $B$27:$E$27, 0), MATCH(B$33, $B$27:$E$27, 0)), 0) -> 0 | C43: =IFERROR(INDEX($B$28:$E$31, MATCH($N43, $B$27:$E$27, 0), MATCH(C$33, $B$27:$E$27, 0)), 0) -> 0 | D43: =IFERROR(INDEX($B$28:$E$31, MATCH($N43, $B$27:$E$27, 0), MATCH(D$33, $B$27:$E$27, 0)), 0) -> 0 | E43: =IFERROR(INDEX($B$28:$E$31, MATCH($N43, $B$27:$E$27, 0), MATCH(E$33, $B$27:$E$27, 0)), 0) -> 0 | F43: =IFERROR(INDEX($B$28:$E$31, MATCH($N43, $B$27:$E$27, 0), MATCH(F$33, $B$27:$E$27, 0)), 0) -> 0 | G43: =IFERROR(INDEX($B$28:$E$31, MATCH($N43, $B$27:$E$27, 0), MATCH(G$33, $B$27:$E$27, 0)), 0) -> 0 | H43: =IFERROR(INDEX($B$28:$E$31, MATCH($N43, $B$27:$E$27, 0), MATCH(H$33, $B$27:$E$27, 0)), 0) -> 0 | I43: =IFERROR(INDEX($B$28:$E$31, MATCH($N43, $B$27:$E$27, 0), MATCH(I$33, $B$27:$E$27, 0)), 0) -> 0 | ... M43: =IFERROR(INDEX($B$28:$E$31, MATCH($N43, $B$27:$E$27, 0), MATCH(M$33, $B$27:$E$27, 0)), 0) -> 0 | N43: U5Y
B44: =IFERROR(INDEX($B$28:$E$31, MATCH($N44, $B$27:$E$27, 0), MATCH(B$33, $B$27:$E$27, 0)), 0) -> 0 | C44: =IFERROR(INDEX($B$28:$E$31, MATCH($N44, $B$27:$E$27, 0), MATCH(C$33, $B$27:$E$27, 0)), 0) -> 0 | D44: =IFERROR(INDEX($B$28:$E$31, MATCH($N44, $B$27:$E$27, 0), MATCH(D$33, $B$27:$E$27, 0)), 0) -> 0 | E44: =IFERROR(INDEX($B$28:$E$31, MATCH($N44, $B$27:$E$27, 0), MATCH(E$33, $B$27:$E$27, 0)), 0) -> 0 | F44: =IFERROR(INDEX($B$28:$E$31, MATCH($N44, $B$27:$E$27, 0), MATCH(F$33, $B$27:$E$27, 0)), 0) -> 0 | G44: =IFERROR(INDEX($B$28:$E$31, MATCH($N44, $B$27:$E$27, 0), MATCH(G$33, $B$27:$E$27, 0)), 0) -> 0 | H44: =IFERROR(INDEX($B$28:$E$31, MATCH($N44, $B$27:$E$27, 0), MATCH(H$33, $B$27:$E$27, 0)), 0) -> 0 | I44: =IFERROR(INDEX($B$28:$E$31, MATCH($N44, $B$27:$E$27, 0), MATCH(I$33, $B$27:$E$27, 0)), 0) -> 0 | ... M44: =IFERROR(INDEX($B$28:$E$31, MATCH($N44, $B$27:$E$27, 0), MATCH(M$33, $B$27:$E$27, 0)), 0) -> 0 | N44: U6X
B45: =IFERROR(INDEX($B$28:$E$31, MATCH($N45, $B$27:$E$27, 0), MATCH(B$33, $B$27:$E$27, 0)), 0) -> 0 | C45: =IFERROR(INDEX($B$28:$E$31, MATCH($N45, $B$27:$E$27, 0), MATCH(C$33, $B$27:$E$27, 0)), 0) -> 0 | D45: =IFERROR(INDEX($B$28:$E$31, MATCH($N45, $B$27:$E$27, 0), MATCH(D$33, $B$27:$E$27, 0)), 0) -> 0 | E45: =IFERROR(INDEX($B$28:$E$31, MATCH($N45, $B$27:$E$27, 0), MATCH(E$33, $B$27:$E$27, 0)), 0) -> 0 | F45: =IFERROR(INDEX($B$28:$E$31, MATCH($N45, $B$27:$E$27, 0), MATCH(F$33, $B$27:$E$27, 0)), 0) -> 0 | G45: =IFERROR(INDEX($B$28:$E$31, MATCH($N45, $B$27:$E$27, 0), MATCH(G$33, $B$27:$E$27, 0)), 0) -> 0 | H45: =IFERROR(INDEX($B$28:$E$31, MATCH($N45, $B$27:$E$27, 0), MATCH(H$33, $B$27:$E$27, 0)), 0) -> 0 | I45: =IFERROR(INDEX($B$28:$E$31, MATCH($N45, $B$27:$E$27, 0), MATCH(I$33, $B$27:$E$27, 0)), 0) -> 0 | ... M45: =IFERROR(INDEX($B$28:$E$31, MATCH($N45, $B$27:$E$27, 0), MATCH(M$33, $B$27:$E$27, 0)), 0) -> 0 | N45: U6Y
...

Sheet MANUAL_ISOSTATICA_3R (3)
A1: PLANTILLA MANUAL - CASO ISOSTÁTICO (HASTA 6 NODOS Y 8 BARRAS - CÁTEDRA ING. ULIANOV)
A2: Cátedra: Análisis Estructural II | Ing. Ulianov Cuba Valencia | Plantilla 100% Automatizada con Capacidad hasta 6 Nodos y 8 Barras
B4: BARRA | C4: INICIO (cm) | E4: FIN (cm) | G4: DX (cm) | H4: DY (cm) | I4: L (cm) | J4: Cx | K4: Cy | L4: A (cm²) | M4: E (Kgf/cm²) | N4: AE/L (Kgf/cm) | P4: COORDENADAS, CONDICIONES DE APOYO Y CARGAS NODALES (HASTA 6 NODOS)
C5: X | D5: Y | E5: X | F5: Y | P5: NUDO | Q5: X (cm) | R5: Y (cm) | S5: TIPO APOYO | T5: Rx | U5: Ry | V5: Px (Kgf) | W5: Py (Kgf)
B6: 1 | C6: =IF(C17="","", IFERROR(VLOOKUP(C17, $P$6:$W$11, 2, FALSE), "")) -> 0 | D6: =IF(C17="","", IFERROR(VLOOKUP(C17, $P$6:$W$11, 3, FALSE), "")) -> 0 | E6: =IF(F17="","", IFERROR(VLOOKUP(F17, $P$6:$W$11, 2, FALSE), "")) -> 200 | F6: =IF(F17="","", IFERROR(VLOOKUP(F17, $P$6:$W$11, 3, FALSE), "")) -> 600 | G6: =IF(OR(C6="",E6=""), "", E6-C6) -> 200 | H6: =IF(OR(D6="",F6=""), "", F6-D6) -> 600 | I6: =IF(OR(G6="",H6=""), "", SQRT(G6^2+H6^2)) -> 632.45553 | J6: =IF(OR(I6="",I6=0), "", G6/I6) -> 0.31622777 | K6: =IF(OR(I6="",I6=0), "", H6/I6) -> 0.9486833 | L6: =IF(C17="","", 20) -> 20 | M6: =IF(C17="","", 150000) -> 150000 | N6: =IF(OR(I6="",I6=0,L6="",M6=""), 0, (L6*M6)/I6) -> 4743.4165 | P6: 1 | Q6: 800 | R6: 800 | S6: Libre | T6: =IF(Q6="","", IF(LEFT(UPPER(TRIM(S6)),4)="FIJO", 1, IF(OR(UPPER(TRIM(S6))="MOVIL X", UPPER(TRIM(S6))="MÓVIL X", UPPER(TRIM(S6))="RODILLO X"), 1, 0))) -> 0 | U6: =IF(Q6="","", IF(LEFT(UPPER(TRIM(S6)),4)="FIJO", 1, IF(OR(UPPER(TRIM(S6))="MOVIL Y", UPPER(TRIM(S6))="MÓVIL Y", UPPER(TRIM(S6))="RODILLO Y", UPPER(TRIM(S6))="MOVIL", UPPER(TRIM(S6))="MÓVIL"), 1, 0))) -> 0 | V6: 1000 | W6: -2000
B7: 2 | C7: =IF(C18="","", IFERROR(VLOOKUP(C18, $P$6:$W$11, 2, FALSE), "")) -> 1000 | D7: =IF(C18="","", IFERROR(VLOOKUP(C18, $P$6:$W$11, 3, FALSE), "")) -> 0 | E7: =IF(F18="","", IFERROR(VLOOKUP(F18, $P$6:$W$11, 2, FALSE), "")) -> 0 | F7: =IF(F18="","", IFERROR(VLOOKUP(F18, $P$6:$W$11, 3, FALSE), "")) -> 0 | G7: =IF(OR(C7="",E7=""), "", E7-C7) -> -1000 | H7: =IF(OR(D7="",F7=""), "", F7-D7) -> 0 | I7: =IF(OR(G7="",H7=""), "", SQRT(G7^2+H7^2)) -> 1000 | J7: =IF(OR(I7="",I7=0), "", G7/I7) -> -1 | K7: =IF(OR(I7="",I7=0), "", H7/I7) -> 0 | L7: =IF(C18="","", 20) -> 20 | M7: =IF(C18="","", 150000) -> 150000 | N7: =IF(OR(I7="",I7=0,L7="",M7=""), 0, (L7*M7)/I7) -> 3000 | P7: 2 | Q7: 200 | R7: 600 | S7: Libre | T7: =IF(Q7="","", IF(LEFT(UPPER(TRIM(S7)),4)="FIJO", 1, IF(OR(UPPER(TRIM(S7))="MOVIL X", UPPER(TRIM(S7))="MÓVIL X", UPPER(TRIM(S7))="RODILLO X"), 1, 0))) -> 0 | U7: =IF(Q7="","", IF(LEFT(UPPER(TRIM(S7)),4)="FIJO", 1, IF(OR(UPPER(TRIM(S7))="MOVIL Y", UPPER(TRIM(S7))="MÓVIL Y", UPPER(TRIM(S7))="RODILLO Y", UPPER(TRIM(S7))="MOVIL", UPPER(TRIM(S7))="MÓVIL"), 1, 0))) -> 0 | V7: 2000 | W7: -1000
B8: 3 | C8: =IF(C19="","", IFERROR(VLOOKUP(C19, $P$6:$W$11, 2, FALSE), "")) -> 800 | D8: =IF(C19="","", IFERROR(VLOOKUP(C19, $P$6:$W$11, 3, FALSE), "")) -> 800 | E8: =IF(F19="","", IFERROR(VLOOKUP(F19, $P$6:$W$11, 2, FALSE), "")) -> 1000 | F8: =IF(F19="","", IFERROR(VLOOKUP(F19, $P$6:$W$11, 3, FALSE), "")) -> 0 | G8: =IF(OR(C8="",E8=""), "", E8-C8) -> 200 | H8: =IF(OR(D8="",F8=""), "", F8-D8) -> -800 | I8: =IF(OR(G8="",H8=""), "", SQRT(G8^2+H8^2)) -> 824.62113 | J8: =IF(OR(I8="",I8=0), "", G8/I8) -> 0.24253563 | K8: =IF(OR(I8="",I8=0), "", H8/I8) -> -0.9701425 | L8: =IF(C19="","", 20) -> 20 | M8: =IF(C19="","", 150000) -> 150000 | N8: =IF(OR(I8="",I8=0,L8="",M8=""), 0, (L8*M8)/I8) -> 3638.0344 | P8: 3 | Q8: 0 | R8: 0 | S8: Móvil Y | T8: =IF(Q8="","", IF(LEFT(UPPER(TRIM(S8)),4)="FIJO", 1, IF(OR(UPPER(TRIM(S8))="MOVIL X", UPPER(TRIM(S8))="MÓVIL X", UPPER(TRIM(S8))="RODILLO X"), 1, 0))) -> 0 | U8: =IF(Q8="","", IF(LEFT(UPPER(TRIM(S8)),4)="FIJO", 1, IF(OR(UPPER(TRIM(S8))="MOVIL Y", UPPER(TRIM(S8))="MÓVIL Y", UPPER(TRIM(S8))="RODILLO Y", UPPER(TRIM(S8))="MOVIL", UPPER(TRIM(S8))="MÓVIL"), 1, 0))) -> 1 | V8: 0 | W8: 0
B9: 4 | C9: =IF(C20="","", IFERROR(VLOOKUP(C20, $P$6:$W$11, 2, FALSE), "")) -> 200 | D9: =IF(C20="","", IFERROR(VLOOKUP(C20, $P$6:$W$11, 3, FALSE), "")) -> 600 | E9: =IF(F20="","", IFERROR(VLOOKUP(F20, $P$6:$W$11, 2, FALSE), "")) -> 1000 | F9: =IF(F20="","", IFERROR(VLOOKUP(F20, $P$6:$W$11, 3, FALSE), "")) -> 0 | G9: =IF(OR(C9="",E9=""), "", E9-C9) -> 800 | H9: =IF(OR(D9="",F9=""), "", F9-D9) -> -600 | I9: =IF(OR(G9="",H9=""), "", SQRT(G9^2+H9^2)) -> 1000 | J9: =IF(OR(I9="",I9=0), "", G9/I9) -> 0.8 | K9: =IF(OR(I9="",I9=0), "", H9/I9) -> -0.6 | L9: =IF(C20="","", 20) -> 20 | M9: =IF(C20="","", 150000) -> 150000 | N9: =IF(OR(I9="",I9=0,L9="",M9=""), 0, (L9*M9)/I9) -> 3000 | P9: 4 | Q9: 1000 | R9: 0 | S9: Fijo | T9: =IF(Q9="","", IF(LEFT(UPPER(TRIM(S9)),4)="FIJO", 1, IF(OR(UPPER(TRIM(S9))="MOVIL X", UPPER(TRIM(S9))="MÓVIL X", UPPER(TRIM(S9))="RODILLO X"), 1, 0))) -> 1 | U9: =IF(Q9="","", IF(LEFT(UPPER(TRIM(S9)),4)="FIJO", 1, IF(OR(UPPER(TRIM(S9))="MOVIL Y", UPPER(TRIM(S9))="MÓVIL Y", UPPER(TRIM(S9))="RODILLO Y", UPPER(TRIM(S9))="MOVIL", UPPER(TRIM(S9))="MÓVIL"), 1, 0))) -> 1 | V9: 0 | W9: 0
B10: 5 | C10: =IF(C21="","", IFERROR(VLOOKUP(C21, $P$6:$W$11, 2, FALSE), "")) -> 200 | D10: =IF(C21="","", IFERROR(VLOOKUP(C21, $P$6:$W$11, 3, FALSE), "")) -> 600 | E10: =IF(F21="","", IFERROR(VLOOKUP(F21, $P$6:$W$11, 2, FALSE), "")) -> 800 | F10: =IF(F21="","", IFERROR(VLOOKUP(F21, $P$6:$W$11, 3, FALSE), "")) -> 800 | G10: =IF(OR(C10="",E10=""), "", E10-C10) -> 600 | H10: =IF(OR(D10="",F10=""), "", F10-D10) -> 200 | I10: =IF(OR(G10="",H10=""), "", SQRT(G10^2+H10^2)) -> 632.45553 | J10: =IF(OR(I10="",I10=0), "", G10/I10) -> 0.9486833 | K10: =IF(OR(I10="",I10=0), "", H10/I10) -> 0.31622777 | L10: =IF(C21="","", 20) -> 20 | M10: =IF(C21="","", 150000) -> 150000 | N10: =IF(OR(I10="",I10=0,L10="",M10=""), 0, (L10*M10)/I10) -> 4743.4165 | P10: 5 | T10: =IF(Q10="","", IF(LEFT(UPPER(TRIM(S10)),4)="FIJO", 1, IF(OR(UPPER(TRIM(S10))="MOVIL X", UPPER(TRIM(S10))="MÓVIL X", UPPER(TRIM(S10))="RODILLO X"), 1, 0))) | U10: =IF(Q10="","", IF(LEFT(UPPER(TRIM(S10)),4)="FIJO", 1, IF(OR(UPPER(TRIM(S10))="MOVIL Y", UPPER(TRIM(S10))="MÓVIL Y", UPPER(TRIM(S10))="RODILLO Y", UPPER(TRIM(S10))="MOVIL", UPPER(TRIM(S10))="MÓVIL"), 1, 0)))
B11: 6 | C11: =IF(C22="","", IFERROR(VLOOKUP(C22, $P$6:$W$11, 2, FALSE), "")) | D11: =IF(C22="","", IFERROR(VLOOKUP(C22, $P$6:$W$11, 3, FALSE), "")) | E11: =IF(F22="","", IFERROR(VLOOKUP(F22, $P$6:$W$11, 2, FALSE), "")) | F11: =IF(F22="","", IFERROR(VLOOKUP(F22, $P$6:$W$11, 3, FALSE), "")) | G11: =IF(OR(C11="",E11=""), "", E11-C11) | H11: =IF(OR(D11="",F11=""), "", F11-D11) | I11: =IF(OR(G11="",H11=""), "", SQRT(G11^2+H11^2)) | J11: =IF(OR(I11="",I11=0), "", G11/I11) | K11: =IF(OR(I11="",I11=0), "", H11/I11) | L11: =IF(C22="","", 10) | M11: =IF(C22="","", 2100000) | N11: =IF(OR(I11="",I11=0,L11="",M11=""), 0, (L11*M11)/I11) -> 0 | P11: 6 | T11: =IF(Q11="","", IF(LEFT(UPPER(TRIM(S11)),4)="FIJO", 1, IF(OR(UPPER(TRIM(S11))="MOVIL X", UPPER(TRIM(S11))="MÓVIL X", UPPER(TRIM(S11))="RODILLO X"), 1, 0))) | U11: =IF(Q11="","", IF(LEFT(UPPER(TRIM(S11)),4)="FIJO", 1, IF(OR(UPPER(TRIM(S11))="MOVIL Y", UPPER(TRIM(S11))="MÓVIL Y", UPPER(TRIM(S11))="RODILLO Y", UPPER(TRIM(S11))="MOVIL", UPPER(TRIM(S11))="MÓVIL"), 1, 0)))
B12: 7 | C12: =IF(C23="","", IFERROR(VLOOKUP(C23, $P$6:$W$11, 2, FALSE), "")) | D12: =IF(C23="","", IFERROR(VLOOKUP(C23, $P$6:$W$11, 3, FALSE), "")) | E12: =IF(F23="","", IFERROR(VLOOKUP(F23, $P$6:$W$11, 2, FALSE), "")) | F12: =IF(F23="","", IFERROR(VLOOKUP(F23, $P$6:$W$11, 3, FALSE), "")) | G12: =IF(OR(C12="",E12=""), "", E12-C12) | H12: =IF(OR(D12="",F12=""), "", F12-D12) | I12: =IF(OR(G12="",H12=""), "", SQRT(G12^2+H12^2)) | J12: =IF(OR(I12="",I12=0), "", G12/I12) | K12: =IF(OR(I12="",I12=0), "", H12/I12) | L12: =IF(C23="","", 10) | M12: =IF(C23="","", 2100000) | N12: =IF(OR(I12="",I12=0,L12="",M12=""), 0, (L12*M12)/I12) -> 0
